{
  "format": "chernobog-debug-block-grid-v2",
  "buildId": "siriocraft_gatehouse-2026-06-27T20-55-02-409Z",
  "displayName": "Roadside Checkpoint",
  "generatedAt": "2026-06-27T20:55:02.409Z",
  "generatorName": "gatehouse",
  "variant": "gatehouse",
  "presetId": "roadside_checkpoint",
  "profile": "vanilla",
  "allowModdedBlocks": false,
  "fallbackToVanilla": true,
  "prompt": "a small faction checkpoint",
  "command": "generate minecraft schematic: a small faction checkpoint",
  "minecraftVersion": "1.21.1",
  "size": {
    "x": 31,
    "y": 19,
    "z": 13
  },
  "palette": [
    "minecraft:air",
    "minecraft:stone_bricks",
    "minecraft:chiseled_stone_bricks",
    "minecraft:iron_bars",
    "minecraft:cracked_stone_bricks",
    "minecraft:mossy_stone_bricks",
    "minecraft:oak_wall_sign[facing=north,waterlogged=false]",
    "minecraft:smooth_stone",
    "minecraft:stone_brick_wall",
    "minecraft:lantern",
    "minecraft:stone_brick_stairs[facing=east,half=bottom,shape=straight,waterlogged=false]",
    "minecraft:stone_brick_stairs[facing=west,half=bottom,shape=straight,waterlogged=false]",
    "minecraft:stone_brick_slab"
  ],
  "blockCount": 2131,
  "features": [
    "two_towers",
    "less_boxy_tower_mass",
    "deep_gate_tunnel",
    "wider_gate_opening",
    "wall_segments",
    "battlements",
    "inset_portcullis_bars",
    "walkway",
    "arrow_slits",
    "tower_cap_rings",
    "buttresses",
    "face_trim",
    "sign_metadata"
  ],
  "blockEntities": [
    {
      "id": "minecraft:oak_sign",
      "kind": "sign",
      "x": 15,
      "y": 5,
      "z": 0,
      "text": [
        "SirioCraft",
        "Gatehouse",
        "",
        ""
      ],
      "label": "Gatehouse name sign",
      "nbtId": "minecraft:sign",
      "nbtStatus": "written",
      "nbtWarnings": []
    }
  ],
  "blockEntityExport": {
    "total": 1,
    "signs": 1,
    "chests": 0,
    "barrels": 0,
    "placeholders": 0,
    "nbtWritten": 1,
    "metadataOnly": 0,
    "warnings": []
  },
  "validation": {
    "ok": true,
    "warnings": [
      "Generator gatehouse did not report required feature: central_gate.",
      "Generator gatehouse did not report required feature: portcullis_bars.",
      "Supported sign block entities are exported as NBT and mirrored in metadata."
    ],
    "errors": []
  },
  "placementWarnings": [
    "Supported sign block entities are exported as NBT and mirrored in metadata."
  ],
  "unsupportedBlockWarnings": [],
  "blockRegistryReport": {
    "profileId": "vanilla",
    "profileDisplayName": "Vanilla Minecraft",
    "allowModdedBlocks": false,
    "fallbackToVanilla": true,
    "allowedNamespaces": [
      "minecraft"
    ],
    "supportedModdedBlocks": [],
    "totalBlocksChecked": 2131,
    "totalPaletteEntriesChecked": 13,
    "changedBlocks": 0,
    "fallbackBlocks": 0,
    "unsupportedBlocks": [],
    "replacements": [],
    "warnings": []
  },
  "blocks": [
    {
      "x": 12,
      "y": 0,
      "z": 0,
      "block": "minecraft:stone_bricks"
    },
    {
      "x": 13,
      "y": 0,
      "z": 0,
      "block": "minecraft:stone_bricks"
    },
    {
      "x": 14,
      "y": 0,
      "z": 0,
      "block": "minecraft:stone_bricks"
    },
    {
      "x": 15,
      "y": 0,
      "z": 0,
      "block": "minecraft:stone_bricks"
    },
    {
      "x": 16,
      "y": 0,
      "z": 0,
      "block": "minecraft:stone_bricks"
    },
    {
      "x": 17,
      "y": 0,
      "z": 0,
      "block": "minecraft:stone_bricks"
    },
    {
      "x": 18,
      "y": 0,
      "z": 0,
      "block": "minecraft:stone_bricks"
    },
    {
      "x": 1,
      "y": 0,
      "z": 1,
      "block": "minecraft:stone_bricks"
    },
    {
      "x": 2,
      "y": 0,
      "z": 1,
      "block": "minecraft:stone_bricks"
    },
    {
      "x": 3,
      "y": 0,
      "z": 1,
      "block": "minecraft:stone_bricks"
    },
    {
      "x": 4,
      "y": 0,
      "z": 1,
      "block": "minecraft:stone_bricks"
    },
    {
      "x": 5,
      "y": 0,
      "z": 1,
      "block": "minecraft:stone_bricks"
    },
    {
      "x": 6,
      "y": 0,
      "z": 1,
      "block": "minecraft:stone_bricks"
    },
    {
      "x": 7,
      "y": 0,
      "z": 1,
      "block": "minecraft:stone_bricks"
    },
    {
      "x": 8,
      "y": 0,
      "z": 1,
      "block": "minecraft:stone_bricks"
    },
    {
      "x": 9,
      "y": 0,
      "z": 1,
      "block": "minecraft:stone_bricks"
    },
    {
      "x": 10,
      "y": 0,
      "z": 1,
      "block": "minecraft:stone_bricks"
    },
    {
      "x": 11,
      "y": 0,
      "z": 1,
      "block": "minecraft:stone_bricks"
    },
    {
      "x": 12,
      "y": 0,
      "z": 1,
      "block": "minecraft:stone_bricks"
    },
    {
      "x": 13,
      "y": 0,
      "z": 1,
      "block": "minecraft:stone_bricks"
    },
    {
      "x": 14,
      "y": 0,
      "z": 1,
      "block": "minecraft:stone_bricks"
    },
    {
      "x": 15,
      "y": 0,
      "z": 1,
      "block": "minecraft:stone_bricks"
    },
    {
      "x": 16,
      "y": 0,
      "z": 1,
      "block": "minecraft:stone_bricks"
    },
    {
      "x": 17,
      "y": 0,
      "z": 1,
      "block": "minecraft:stone_bricks"
    },
    {
      "x": 18,
      "y": 0,
      "z": 1,
      "block": "minecraft:stone_bricks"
    },
    {
      "x": 19,
      "y": 0,
      "z": 1,
      "block": "minecraft:stone_bricks"
    },
    {
      "x": 20,
      "y": 0,
      "z": 1,
      "block": "minecraft:stone_bricks"
    },
    {
      "x": 21,
      "y": 0,
      "z": 1,
      "block": "minecraft:stone_bricks"
    },
    {
      "x": 22,
      "y": 0,
      "z": 1,
      "block": "minecraft:stone_bricks"
    },
    {
      "x": 23,
      "y": 0,
      "z": 1,
      "block": "minecraft:stone_bricks"
    },
    {
      "x": 24,
      "y": 0,
      "z": 1,
      "block": "minecraft:stone_bricks"
    },
    {
      "x": 25,
      "y": 0,
      "z": 1,
      "block": "minecraft:stone_bricks"
    },
    {
      "x": 26,
      "y": 0,
      "z": 1,
      "block": "minecraft:stone_bricks"
    },
    {
      "x": 27,
      "y": 0,
      "z": 1,
      "block": "minecraft:stone_bricks"
    },
    {
      "x": 28,
      "y": 0,
      "z": 1,
      "block": "minecraft:stone_bricks"
    },
    {
      "x": 29,
      "y": 0,
      "z": 1,
      "block": "minecraft:stone_bricks"
    },
    {
      "x": 1,
      "y": 0,
      "z": 2,
      "block": "minecraft:stone_bricks"
    },
    {
      "x": 2,
      "y": 0,
      "z": 2,
      "block": "minecraft:stone_bricks"
    },
    {
      "x": 3,
      "y": 0,
      "z": 2,
      "block": "minecraft:stone_bricks"
    },
    {
      "x": 4,
      "y": 0,
      "z": 2,
      "block": "minecraft:stone_bricks"
    },
    {
      "x": 5,
      "y": 0,
      "z": 2,
      "block": "minecraft:stone_bricks"
    },
    {
      "x": 6,
      "y": 0,
      "z": 2,
      "block": "minecraft:stone_bricks"
    },
    {
      "x": 7,
      "y": 0,
      "z": 2,
      "block": "minecraft:stone_bricks"
    },
    {
      "x": 8,
      "y": 0,
      "z": 2,
      "block": "minecraft:stone_bricks"
    },
    {
      "x": 9,
      "y": 0,
      "z": 2,
      "block": "minecraft:stone_bricks"
    },
    {
      "x": 10,
      "y": 0,
      "z": 2,
      "block": "minecraft:stone_bricks"
    },
    {
      "x": 11,
      "y": 0,
      "z": 2,
      "block": "minecraft:stone_bricks"
    },
    {
      "x": 12,
      "y": 0,
      "z": 2,
      "block": "minecraft:stone_bricks"
    },
    {
      "x": 13,
      "y": 0,
      "z": 2,
      "block": "minecraft:stone_bricks"
    },
    {
      "x": 14,
      "y": 0,
      "z": 2,
      "block": "minecraft:stone_bricks"
    },
    {
      "x": 15,
      "y": 0,
      "z": 2,
      "block": "minecraft:stone_bricks"
    },
    {
      "x": 16,
      "y": 0,
      "z": 2,
      "block": "minecraft:stone_bricks"
    },
    {
      "x": 17,
      "y": 0,
      "z": 2,
      "block": "minecraft:stone_bricks"
    },
    {
      "x": 18,
      "y": 0,
      "z": 2,
      "block": "minecraft:stone_bricks"
    },
    {
      "x": 19,
      "y": 0,
      "z": 2,
      "block": "minecraft:stone_bricks"
    },
    {
      "x": 20,
      "y": 0,
      "z": 2,
      "block": "minecraft:stone_bricks"
    },
    {
      "x": 21,
      "y": 0,
      "z": 2,
      "block": "minecraft:stone_bricks"
    },
    {
      "x": 22,
      "y": 0,
      "z": 2,
      "block": "minecraft:stone_bricks"
    },
    {
      "x": 23,
      "y": 0,
      "z": 2,
      "block": "minecraft:stone_bricks"
    },
    {
      "x": 24,
      "y": 0,
      "z": 2,
      "block": "minecraft:stone_bricks"
    },
    {
      "x": 25,
      "y": 0,
      "z": 2,
      "block": "minecraft:stone_bricks"
    },
    {
      "x": 26,
      "y": 0,
      "z": 2,
      "block": "minecraft:stone_bricks"
    },
    {
      "x": 27,
      "y": 0,
      "z": 2,
      "block": "minecraft:stone_bricks"
    },
    {
      "x": 28,
      "y": 0,
      "z": 2,
      "block": "minecraft:stone_bricks"
    },
    {
      "x": 29,
      "y": 0,
      "z": 2,
      "block": "minecraft:stone_bricks"
    },
    {
      "x": 1,
      "y": 0,
      "z": 3,
      "block": "minecraft:stone_bricks"
    },
    {
      "x": 2,
      "y": 0,
      "z": 3,
      "block": "minecraft:stone_bricks"
    },
    {
      "x": 3,
      "y": 0,
      "z": 3,
      "block": "minecraft:stone_bricks"
    },
    {
      "x": 4,
      "y": 0,
      "z": 3,
      "block": "minecraft:stone_bricks"
    },
    {
      "x": 5,
      "y": 0,
      "z": 3,
      "block": "minecraft:stone_bricks"
    },
    {
      "x": 6,
      "y": 0,
      "z": 3,
      "block": "minecraft:stone_bricks"
    },
    {
      "x": 7,
      "y": 0,
      "z": 3,
      "block": "minecraft:stone_bricks"
    },
    {
      "x": 8,
      "y": 0,
      "z": 3,
      "block": "minecraft:stone_bricks"
    },
    {
      "x": 9,
      "y": 0,
      "z": 3,
      "block": "minecraft:stone_bricks"
    },
    {
      "x": 10,
      "y": 0,
      "z": 3,
      "block": "minecraft:stone_bricks"
    },
    {
      "x": 11,
      "y": 0,
      "z": 3,
      "block": "minecraft:stone_bricks"
    },
    {
      "x": 12,
      "y": 0,
      "z": 3,
      "block": "minecraft:stone_bricks"
    },
    {
      "x": 13,
      "y": 0,
      "z": 3,
      "block": "minecraft:stone_bricks"
    },
    {
      "x": 14,
      "y": 0,
      "z": 3,
      "block": "minecraft:stone_bricks"
    },
    {
      "x": 15,
      "y": 0,
      "z": 3,
      "block": "minecraft:stone_bricks"
    },
    {
      "x": 16,
      "y": 0,
      "z": 3,
      "block": "minecraft:stone_bricks"
    },
    {
      "x": 17,
      "y": 0,
      "z": 3,
      "block": "minecraft:stone_bricks"
    },
    {
      "x": 18,
      "y": 0,
      "z": 3,
      "block": "minecraft:stone_bricks"
    },
    {
      "x": 19,
      "y": 0,
      "z": 3,
      "block": "minecraft:stone_bricks"
    },
    {
      "x": 20,
      "y": 0,
      "z": 3,
      "block": "minecraft:stone_bricks"
    },
    {
      "x": 21,
      "y": 0,
      "z": 3,
      "block": "minecraft:stone_bricks"
    },
    {
      "x": 22,
      "y": 0,
      "z": 3,
      "block": "minecraft:stone_bricks"
    },
    {
      "x": 23,
      "y": 0,
      "z": 3,
      "block": "minecraft:stone_bricks"
    },
    {
      "x": 24,
      "y": 0,
      "z": 3,
      "block": "minecraft:stone_bricks"
    },
    {
      "x": 25,
      "y": 0,
      "z": 3,
      "block": "minecraft:stone_bricks"
    },
    {
      "x": 26,
      "y": 0,
      "z": 3,
      "block": "minecraft:stone_bricks"
    },
    {
      "x": 27,
      "y": 0,
      "z": 3,
      "block": "minecraft:stone_bricks"
    },
    {
      "x": 28,
      "y": 0,
      "z": 3,
      "block": "minecraft:stone_bricks"
    },
    {
      "x": 29,
      "y": 0,
      "z": 3,
      "block": "minecraft:stone_bricks"
    },
    {
      "x": 1,
      "y": 0,
      "z": 4,
      "block": "minecraft:stone_bricks"
    },
    {
      "x": 2,
      "y": 0,
      "z": 4,
      "block": "minecraft:stone_bricks"
    },
    {
      "x": 3,
      "y": 0,
      "z": 4,
      "block": "minecraft:stone_bricks"
    },
    {
      "x": 4,
      "y": 0,
      "z": 4,
      "block": "minecraft:stone_bricks"
    },
    {
      "x": 5,
      "y": 0,
      "z": 4,
      "block": "minecraft:stone_bricks"
    },
    {
      "x": 6,
      "y": 0,
      "z": 4,
      "block": "minecraft:stone_bricks"
    },
    {
      "x": 7,
      "y": 0,
      "z": 4,
      "block": "minecraft:stone_bricks"
    },
    {
      "x": 8,
      "y": 0,
      "z": 4,
      "block": "minecraft:stone_bricks"
    },
    {
      "x": 9,
      "y": 0,
      "z": 4,
      "block": "minecraft:stone_bricks"
    },
    {
      "x": 10,
      "y": 0,
      "z": 4,
      "block": "minecraft:stone_bricks"
    },
    {
      "x": 11,
      "y": 0,
      "z": 4,
      "block": "minecraft:stone_bricks"
    },
    {
      "x": 12,
      "y": 0,
      "z": 4,
      "block": "minecraft:stone_bricks"
    },
    {
      "x": 13,
      "y": 0,
      "z": 4,
      "block": "minecraft:stone_bricks"
    },
    {
      "x": 14,
      "y": 0,
      "z": 4,
      "block": "minecraft:stone_bricks"
    },
    {
      "x": 15,
      "y": 0,
      "z": 4,
      "block": "minecraft:stone_bricks"
    },
    {
      "x": 16,
      "y": 0,
      "z": 4,
      "block": "minecraft:stone_bricks"
    },
    {
      "x": 17,
      "y": 0,
      "z": 4,
      "block": "minecraft:stone_bricks"
    },
    {
      "x": 18,
      "y": 0,
      "z": 4,
      "block": "minecraft:stone_bricks"
    },
    {
      "x": 19,
      "y": 0,
      "z": 4,
      "block": "minecraft:stone_bricks"
    },
    {
      "x": 20,
      "y": 0,
      "z": 4,
      "block": "minecraft:stone_bricks"
    },
    {
      "x": 21,
      "y": 0,
      "z": 4,
      "block": "minecraft:stone_bricks"
    },
    {
      "x": 22,
      "y": 0,
      "z": 4,
      "block": "minecraft:stone_bricks"
    },
    {
      "x": 23,
      "y": 0,
      "z": 4,
      "block": "minecraft:stone_bricks"
    },
    {
      "x": 24,
      "y": 0,
      "z": 4,
      "block": "minecraft:stone_bricks"
    },
    {
      "x": 25,
      "y": 0,
      "z": 4,
      "block": "minecraft:stone_bricks"
    },
    {
      "x": 26,
      "y": 0,
      "z": 4,
      "block": "minecraft:stone_bricks"
    },
    {
      "x": 27,
      "y": 0,
      "z": 4,
      "block": "minecraft:stone_bricks"
    },
    {
      "x": 28,
      "y": 0,
      "z": 4,
      "block": "minecraft:stone_bricks"
    },
    {
      "x": 29,
      "y": 0,
      "z": 4,
      "block": "minecraft:stone_bricks"
    },
    {
      "x": 1,
      "y": 0,
      "z": 5,
      "block": "minecraft:stone_bricks"
    },
    {
      "x": 2,
      "y": 0,
      "z": 5,
      "block": "minecraft:stone_bricks"
    },
    {
      "x": 3,
      "y": 0,
      "z": 5,
      "block": "minecraft:stone_bricks"
    },
    {
      "x": 4,
      "y": 0,
      "z": 5,
      "block": "minecraft:stone_bricks"
    },
    {
      "x": 5,
      "y": 0,
      "z": 5,
      "block": "minecraft:stone_bricks"
    },
    {
      "x": 6,
      "y": 0,
      "z": 5,
      "block": "minecraft:stone_bricks"
    },
    {
      "x": 7,
      "y": 0,
      "z": 5,
      "block": "minecraft:stone_bricks"
    },
    {
      "x": 8,
      "y": 0,
      "z": 5,
      "block": "minecraft:stone_bricks"
    },
    {
      "x": 9,
      "y": 0,
      "z": 5,
      "block": "minecraft:stone_bricks"
    },
    {
      "x": 10,
      "y": 0,
      "z": 5,
      "block": "minecraft:stone_bricks"
    },
    {
      "x": 11,
      "y": 0,
      "z": 5,
      "block": "minecraft:stone_bricks"
    },
    {
      "x": 12,
      "y": 0,
      "z": 5,
      "block": "minecraft:stone_bricks"
    },
    {
      "x": 13,
      "y": 0,
      "z": 5,
      "block": "minecraft:stone_bricks"
    },
    {
      "x": 14,
      "y": 0,
      "z": 5,
      "block": "minecraft:stone_bricks"
    },
    {
      "x": 15,
      "y": 0,
      "z": 5,
      "block": "minecraft:stone_bricks"
    },
    {
      "x": 16,
      "y": 0,
      "z": 5,
      "block": "minecraft:stone_bricks"
    },
    {
      "x": 17,
      "y": 0,
      "z": 5,
      "block": "minecraft:stone_bricks"
    },
    {
      "x": 18,
      "y": 0,
      "z": 5,
      "block": "minecraft:stone_bricks"
    },
    {
      "x": 19,
      "y": 0,
      "z": 5,
      "block": "minecraft:stone_bricks"
    },
    {
      "x": 20,
      "y": 0,
      "z": 5,
      "block": "minecraft:stone_bricks"
    },
    {
      "x": 21,
      "y": 0,
      "z": 5,
      "block": "minecraft:stone_bricks"
    },
    {
      "x": 22,
      "y": 0,
      "z": 5,
      "block": "minecraft:stone_bricks"
    },
    {
      "x": 23,
      "y": 0,
      "z": 5,
      "block": "minecraft:stone_bricks"
    },
    {
      "x": 24,
      "y": 0,
      "z": 5,
      "block": "minecraft:stone_bricks"
    },
    {
      "x": 25,
      "y": 0,
      "z": 5,
      "block": "minecraft:stone_bricks"
    },
    {
      "x": 26,
      "y": 0,
      "z": 5,
      "block": "minecraft:stone_bricks"
    },
    {
      "x": 27,
      "y": 0,
      "z": 5,
      "block": "minecraft:stone_bricks"
    },
    {
      "x": 28,
      "y": 0,
      "z": 5,
      "block": "minecraft:stone_bricks"
    },
    {
      "x": 29,
      "y": 0,
      "z": 5,
      "block": "minecraft:stone_bricks"
    },
    {
      "x": 1,
      "y": 0,
      "z": 6,
      "block": "minecraft:stone_bricks"
    },
    {
      "x": 2,
      "y": 0,
      "z": 6,
      "block": "minecraft:stone_bricks"
    },
    {
      "x": 3,
      "y": 0,
      "z": 6,
      "block": "minecraft:stone_bricks"
    },
    {
      "x": 4,
      "y": 0,
      "z": 6,
      "block": "minecraft:stone_bricks"
    },
    {
      "x": 5,
      "y": 0,
      "z": 6,
      "block": "minecraft:stone_bricks"
    },
    {
      "x": 6,
      "y": 0,
      "z": 6,
      "block": "minecraft:stone_bricks"
    },
    {
      "x": 7,
      "y": 0,
      "z": 6,
      "block": "minecraft:stone_bricks"
    },
    {
      "x": 8,
      "y": 0,
      "z": 6,
      "block": "minecraft:stone_bricks"
    },
    {
      "x": 9,
      "y": 0,
      "z": 6,
      "block": "minecraft:stone_bricks"
    },
    {
      "x": 10,
      "y": 0,
      "z": 6,
      "block": "minecraft:stone_bricks"
    },
    {
      "x": 11,
      "y": 0,
      "z": 6,
      "block": "minecraft:stone_bricks"
    },
    {
      "x": 12,
      "y": 0,
      "z": 6,
      "block": "minecraft:stone_bricks"
    },
    {
      "x": 13,
      "y": 0,
      "z": 6,
      "block": "minecraft:stone_bricks"
    },
    {
      "x": 14,
      "y": 0,
      "z": 6,
      "block": "minecraft:stone_bricks"
    },
    {
      "x": 15,
      "y": 0,
      "z": 6,
      "block": "minecraft:stone_bricks"
    },
    {
      "x": 16,
      "y": 0,
      "z": 6,
      "block": "minecraft:stone_bricks"
    },
    {
      "x": 17,
      "y": 0,
      "z": 6,
      "block": "minecraft:stone_bricks"
    },
    {
      "x": 18,
      "y": 0,
      "z": 6,
      "block": "minecraft:stone_bricks"
    },
    {
      "x": 19,
      "y": 0,
      "z": 6,
      "block": "minecraft:stone_bricks"
    },
    {
      "x": 20,
      "y": 0,
      "z": 6,
      "block": "minecraft:stone_bricks"
    },
    {
      "x": 21,
      "y": 0,
      "z": 6,
      "block": "minecraft:stone_bricks"
    },
    {
      "x": 22,
      "y": 0,
      "z": 6,
      "block": "minecraft:stone_bricks"
    },
    {
      "x": 23,
      "y": 0,
      "z": 6,
      "block": "minecraft:stone_bricks"
    },
    {
      "x": 24,
      "y": 0,
      "z": 6,
      "block": "minecraft:stone_bricks"
    },
    {
      "x": 25,
      "y": 0,
      "z": 6,
      "block": "minecraft:stone_bricks"
    },
    {
      "x": 26,
      "y": 0,
      "z": 6,
      "block": "minecraft:stone_bricks"
    },
    {
      "x": 27,
      "y": 0,
      "z": 6,
      "block": "minecraft:stone_bricks"
    },
    {
      "x": 28,
      "y": 0,
      "z": 6,
      "block": "minecraft:stone_bricks"
    },
    {
      "x": 29,
      "y": 0,
      "z": 6,
      "block": "minecraft:stone_bricks"
    },
    {
      "x": 1,
      "y": 0,
      "z": 7,
      "block": "minecraft:stone_bricks"
    },
    {
      "x": 2,
      "y": 0,
      "z": 7,
      "block": "minecraft:stone_bricks"
    },
    {
      "x": 3,
      "y": 0,
      "z": 7,
      "block": "minecraft:stone_bricks"
    },
    {
      "x": 4,
      "y": 0,
      "z": 7,
      "block": "minecraft:stone_bricks"
    },
    {
      "x": 5,
      "y": 0,
      "z": 7,
      "block": "minecraft:stone_bricks"
    },
    {
      "x": 6,
      "y": 0,
      "z": 7,
      "block": "minecraft:stone_bricks"
    },
    {
      "x": 7,
      "y": 0,
      "z": 7,
      "block": "minecraft:stone_bricks"
    },
    {
      "x": 8,
      "y": 0,
      "z": 7,
      "block": "minecraft:stone_bricks"
    },
    {
      "x": 9,
      "y": 0,
      "z": 7,
      "block": "minecraft:stone_bricks"
    },
    {
      "x": 10,
      "y": 0,
      "z": 7,
      "block": "minecraft:stone_bricks"
    },
    {
      "x": 11,
      "y": 0,
      "z": 7,
      "block": "minecraft:stone_bricks"
    },
    {
      "x": 12,
      "y": 0,
      "z": 7,
      "block": "minecraft:stone_bricks"
    },
    {
      "x": 13,
      "y": 0,
      "z": 7,
      "block": "minecraft:stone_bricks"
    },
    {
      "x": 14,
      "y": 0,
      "z": 7,
      "block": "minecraft:stone_bricks"
    },
    {
      "x": 15,
      "y": 0,
      "z": 7,
      "block": "minecraft:stone_bricks"
    },
    {
      "x": 16,
      "y": 0,
      "z": 7,
      "block": "minecraft:stone_bricks"
    },
    {
      "x": 17,
      "y": 0,
      "z": 7,
      "block": "minecraft:stone_bricks"
    },
    {
      "x": 18,
      "y": 0,
      "z": 7,
      "block": "minecraft:stone_bricks"
    },
    {
      "x": 19,
      "y": 0,
      "z": 7,
      "block": "minecraft:stone_bricks"
    },
    {
      "x": 20,
      "y": 0,
      "z": 7,
      "block": "minecraft:stone_bricks"
    },
    {
      "x": 21,
      "y": 0,
      "z": 7,
      "block": "minecraft:stone_bricks"
    },
    {
      "x": 22,
      "y": 0,
      "z": 7,
      "block": "minecraft:stone_bricks"
    },
    {
      "x": 23,
      "y": 0,
      "z": 7,
      "block": "minecraft:stone_bricks"
    },
    {
      "x": 24,
      "y": 0,
      "z": 7,
      "block": "minecraft:stone_bricks"
    },
    {
      "x": 25,
      "y": 0,
      "z": 7,
      "block": "minecraft:stone_bricks"
    },
    {
      "x": 26,
      "y": 0,
      "z": 7,
      "block": "minecraft:stone_bricks"
    },
    {
      "x": 27,
      "y": 0,
      "z": 7,
      "block": "minecraft:stone_bricks"
    },
    {
      "x": 28,
      "y": 0,
      "z": 7,
      "block": "minecraft:stone_bricks"
    },
    {
      "x": 29,
      "y": 0,
      "z": 7,
      "block": "minecraft:stone_bricks"
    },
    {
      "x": 1,
      "y": 0,
      "z": 8,
      "block": "minecraft:stone_bricks"
    },
    {
      "x": 2,
      "y": 0,
      "z": 8,
      "block": "minecraft:stone_bricks"
    },
    {
      "x": 3,
      "y": 0,
      "z": 8,
      "block": "minecraft:stone_bricks"
    },
    {
      "x": 4,
      "y": 0,
      "z": 8,
      "block": "minecraft:stone_bricks"
    },
    {
      "x": 5,
      "y": 0,
      "z": 8,
      "block": "minecraft:stone_bricks"
    },
    {
      "x": 6,
      "y": 0,
      "z": 8,
      "block": "minecraft:stone_bricks"
    },
    {
      "x": 7,
      "y": 0,
      "z": 8,
      "block": "minecraft:stone_bricks"
    },
    {
      "x": 8,
      "y": 0,
      "z": 8,
      "block": "minecraft:stone_bricks"
    },
    {
      "x": 9,
      "y": 0,
      "z": 8,
      "block": "minecraft:stone_bricks"
    },
    {
      "x": 10,
      "y": 0,
      "z": 8,
      "block": "minecraft:stone_bricks"
    },
    {
      "x": 11,
      "y": 0,
      "z": 8,
      "block": "minecraft:stone_bricks"
    },
    {
      "x": 12,
      "y": 0,
      "z": 8,
      "block": "minecraft:stone_bricks"
    },
    {
      "x": 13,
      "y": 0,
      "z": 8,
      "block": "minecraft:stone_bricks"
    },
    {
      "x": 14,
      "y": 0,
      "z": 8,
      "block": "minecraft:stone_bricks"
    },
    {
      "x": 15,
      "y": 0,
      "z": 8,
      "block": "minecraft:stone_bricks"
    },
    {
      "x": 16,
      "y": 0,
      "z": 8,
      "block": "minecraft:stone_bricks"
    },
    {
      "x": 17,
      "y": 0,
      "z": 8,
      "block": "minecraft:stone_bricks"
    },
    {
      "x": 18,
      "y": 0,
      "z": 8,
      "block": "minecraft:stone_bricks"
    },
    {
      "x": 19,
      "y": 0,
      "z": 8,
      "block": "minecraft:stone_bricks"
    },
    {
      "x": 20,
      "y": 0,
      "z": 8,
      "block": "minecraft:stone_bricks"
    },
    {
      "x": 21,
      "y": 0,
      "z": 8,
      "block": "minecraft:stone_bricks"
    },
    {
      "x": 22,
      "y": 0,
      "z": 8,
      "block": "minecraft:stone_bricks"
    },
    {
      "x": 23,
      "y": 0,
      "z": 8,
      "block": "minecraft:stone_bricks"
    },
    {
      "x": 24,
      "y": 0,
      "z": 8,
      "block": "minecraft:stone_bricks"
    },
    {
      "x": 25,
      "y": 0,
      "z": 8,
      "block": "minecraft:stone_bricks"
    },
    {
      "x": 26,
      "y": 0,
      "z": 8,
      "block": "minecraft:stone_bricks"
    },
    {
      "x": 27,
      "y": 0,
      "z": 8,
      "block": "minecraft:stone_bricks"
    },
    {
      "x": 28,
      "y": 0,
      "z": 8,
      "block": "minecraft:stone_bricks"
    },
    {
      "x": 29,
      "y": 0,
      "z": 8,
      "block": "minecraft:stone_bricks"
    },
    {
      "x": 1,
      "y": 0,
      "z": 9,
      "block": "minecraft:stone_bricks"
    },
    {
      "x": 2,
      "y": 0,
      "z": 9,
      "block": "minecraft:stone_bricks"
    },
    {
      "x": 3,
      "y": 0,
      "z": 9,
      "block": "minecraft:stone_bricks"
    },
    {
      "x": 4,
      "y": 0,
      "z": 9,
      "block": "minecraft:stone_bricks"
    },
    {
      "x": 5,
      "y": 0,
      "z": 9,
      "block": "minecraft:stone_bricks"
    },
    {
      "x": 6,
      "y": 0,
      "z": 9,
      "block": "minecraft:stone_bricks"
    },
    {
      "x": 7,
      "y": 0,
      "z": 9,
      "block": "minecraft:stone_bricks"
    },
    {
      "x": 8,
      "y": 0,
      "z": 9,
      "block": "minecraft:stone_bricks"
    },
    {
      "x": 9,
      "y": 0,
      "z": 9,
      "block": "minecraft:stone_bricks"
    },
    {
      "x": 10,
      "y": 0,
      "z": 9,
      "block": "minecraft:stone_bricks"
    },
    {
      "x": 11,
      "y": 0,
      "z": 9,
      "block": "minecraft:stone_bricks"
    },
    {
      "x": 12,
      "y": 0,
      "z": 9,
      "block": "minecraft:stone_bricks"
    },
    {
      "x": 13,
      "y": 0,
      "z": 9,
      "block": "minecraft:stone_bricks"
    },
    {
      "x": 14,
      "y": 0,
      "z": 9,
      "block": "minecraft:stone_bricks"
    },
    {
      "x": 15,
      "y": 0,
      "z": 9,
      "block": "minecraft:stone_bricks"
    },
    {
      "x": 16,
      "y": 0,
      "z": 9,
      "block": "minecraft:stone_bricks"
    },
    {
      "x": 17,
      "y": 0,
      "z": 9,
      "block": "minecraft:stone_bricks"
    },
    {
      "x": 18,
      "y": 0,
      "z": 9,
      "block": "minecraft:stone_bricks"
    },
    {
      "x": 19,
      "y": 0,
      "z": 9,
      "block": "minecraft:stone_bricks"
    },
    {
      "x": 20,
      "y": 0,
      "z": 9,
      "block": "minecraft:stone_bricks"
    },
    {
      "x": 21,
      "y": 0,
      "z": 9,
      "block": "minecraft:stone_bricks"
    },
    {
      "x": 22,
      "y": 0,
      "z": 9,
      "block": "minecraft:stone_bricks"
    },
    {
      "x": 23,
      "y": 0,
      "z": 9,
      "block": "minecraft:stone_bricks"
    },
    {
      "x": 24,
      "y": 0,
      "z": 9,
      "block": "minecraft:stone_bricks"
    },
    {
      "x": 25,
      "y": 0,
      "z": 9,
      "block": "minecraft:stone_bricks"
    },
    {
      "x": 26,
      "y": 0,
      "z": 9,
      "block": "minecraft:stone_bricks"
    },
    {
      "x": 27,
      "y": 0,
      "z": 9,
      "block": "minecraft:stone_bricks"
    },
    {
      "x": 28,
      "y": 0,
      "z": 9,
      "block": "minecraft:stone_bricks"
    },
    {
      "x": 29,
      "y": 0,
      "z": 9,
      "block": "minecraft:stone_bricks"
    },
    {
      "x": 1,
      "y": 0,
      "z": 10,
      "block": "minecraft:stone_bricks"
    },
    {
      "x": 2,
      "y": 0,
      "z": 10,
      "block": "minecraft:stone_bricks"
    },
    {
      "x": 3,
      "y": 0,
      "z": 10,
      "block": "minecraft:stone_bricks"
    },
    {
      "x": 4,
      "y": 0,
      "z": 10,
      "block": "minecraft:stone_bricks"
    },
    {
      "x": 5,
      "y": 0,
      "z": 10,
      "block": "minecraft:stone_bricks"
    },
    {
      "x": 6,
      "y": 0,
      "z": 10,
      "block": "minecraft:stone_bricks"
    },
    {
      "x": 7,
      "y": 0,
      "z": 10,
      "block": "minecraft:stone_bricks"
    },
    {
      "x": 8,
      "y": 0,
      "z": 10,
      "block": "minecraft:stone_bricks"
    },
    {
      "x": 9,
      "y": 0,
      "z": 10,
      "block": "minecraft:stone_bricks"
    },
    {
      "x": 10,
      "y": 0,
      "z": 10,
      "block": "minecraft:stone_bricks"
    },
    {
      "x": 11,
      "y": 0,
      "z": 10,
      "block": "minecraft:stone_bricks"
    },
    {
      "x": 12,
      "y": 0,
      "z": 10,
      "block": "minecraft:stone_bricks"
    },
    {
      "x": 13,
      "y": 0,
      "z": 10,
      "block": "minecraft:stone_bricks"
    },
    {
      "x": 14,
      "y": 0,
      "z": 10,
      "block": "minecraft:stone_bricks"
    },
    {
      "x": 15,
      "y": 0,
      "z": 10,
      "block": "minecraft:stone_bricks"
    },
    {
      "x": 16,
      "y": 0,
      "z": 10,
      "block": "minecraft:stone_bricks"
    },
    {
      "x": 17,
      "y": 0,
      "z": 10,
      "block": "minecraft:stone_bricks"
    },
    {
      "x": 18,
      "y": 0,
      "z": 10,
      "block": "minecraft:stone_bricks"
    },
    {
      "x": 19,
      "y": 0,
      "z": 10,
      "block": "minecraft:stone_bricks"
    },
    {
      "x": 20,
      "y": 0,
      "z": 10,
      "block": "minecraft:stone_bricks"
    },
    {
      "x": 21,
      "y": 0,
      "z": 10,
      "block": "minecraft:stone_bricks"
    },
    {
      "x": 22,
      "y": 0,
      "z": 10,
      "block": "minecraft:stone_bricks"
    },
    {
      "x": 23,
      "y": 0,
      "z": 10,
      "block": "minecraft:stone_bricks"
    },
    {
      "x": 24,
      "y": 0,
      "z": 10,
      "block": "minecraft:stone_bricks"
    },
    {
      "x": 25,
      "y": 0,
      "z": 10,
      "block": "minecraft:stone_bricks"
    },
    {
      "x": 26,
      "y": 0,
      "z": 10,
      "block": "minecraft:stone_bricks"
    },
    {
      "x": 27,
      "y": 0,
      "z": 10,
      "block": "minecraft:stone_bricks"
    },
    {
      "x": 28,
      "y": 0,
      "z": 10,
      "block": "minecraft:stone_bricks"
    },
    {
      "x": 29,
      "y": 0,
      "z": 10,
      "block": "minecraft:stone_bricks"
    },
    {
      "x": 1,
      "y": 0,
      "z": 11,
      "block": "minecraft:stone_bricks"
    },
    {
      "x": 2,
      "y": 0,
      "z": 11,
      "block": "minecraft:stone_bricks"
    },
    {
      "x": 3,
      "y": 0,
      "z": 11,
      "block": "minecraft:stone_bricks"
    },
    {
      "x": 4,
      "y": 0,
      "z": 11,
      "block": "minecraft:stone_bricks"
    },
    {
      "x": 5,
      "y": 0,
      "z": 11,
      "block": "minecraft:stone_bricks"
    },
    {
      "x": 6,
      "y": 0,
      "z": 11,
      "block": "minecraft:stone_bricks"
    },
    {
      "x": 7,
      "y": 0,
      "z": 11,
      "block": "minecraft:stone_bricks"
    },
    {
      "x": 8,
      "y": 0,
      "z": 11,
      "block": "minecraft:stone_bricks"
    },
    {
      "x": 9,
      "y": 0,
      "z": 11,
      "block": "minecraft:stone_bricks"
    },
    {
      "x": 10,
      "y": 0,
      "z": 11,
      "block": "minecraft:stone_bricks"
    },
    {
      "x": 11,
      "y": 0,
      "z": 11,
      "block": "minecraft:stone_bricks"
    },
    {
      "x": 12,
      "y": 0,
      "z": 11,
      "block": "minecraft:stone_bricks"
    },
    {
      "x": 13,
      "y": 0,
      "z": 11,
      "block": "minecraft:stone_bricks"
    },
    {
      "x": 14,
      "y": 0,
      "z": 11,
      "block": "minecraft:stone_bricks"
    },
    {
      "x": 15,
      "y": 0,
      "z": 11,
      "block": "minecraft:stone_bricks"
    },
    {
      "x": 16,
      "y": 0,
      "z": 11,
      "block": "minecraft:stone_bricks"
    },
    {
      "x": 17,
      "y": 0,
      "z": 11,
      "block": "minecraft:stone_bricks"
    },
    {
      "x": 18,
      "y": 0,
      "z": 11,
      "block": "minecraft:stone_bricks"
    },
    {
      "x": 19,
      "y": 0,
      "z": 11,
      "block": "minecraft:stone_bricks"
    },
    {
      "x": 20,
      "y": 0,
      "z": 11,
      "block": "minecraft:stone_bricks"
    },
    {
      "x": 21,
      "y": 0,
      "z": 11,
      "block": "minecraft:stone_bricks"
    },
    {
      "x": 22,
      "y": 0,
      "z": 11,
      "block": "minecraft:stone_bricks"
    },
    {
      "x": 23,
      "y": 0,
      "z": 11,
      "block": "minecraft:stone_bricks"
    },
    {
      "x": 24,
      "y": 0,
      "z": 11,
      "block": "minecraft:stone_bricks"
    },
    {
      "x": 25,
      "y": 0,
      "z": 11,
      "block": "minecraft:stone_bricks"
    },
    {
      "x": 26,
      "y": 0,
      "z": 11,
      "block": "minecraft:stone_bricks"
    },
    {
      "x": 27,
      "y": 0,
      "z": 11,
      "block": "minecraft:stone_bricks"
    },
    {
      "x": 28,
      "y": 0,
      "z": 11,
      "block": "minecraft:stone_bricks"
    },
    {
      "x": 29,
      "y": 0,
      "z": 11,
      "block": "minecraft:stone_bricks"
    },
    {
      "x": 12,
      "y": 0,
      "z": 12,
      "block": "minecraft:stone_bricks"
    },
    {
      "x": 13,
      "y": 0,
      "z": 12,
      "block": "minecraft:stone_bricks"
    },
    {
      "x": 14,
      "y": 0,
      "z": 12,
      "block": "minecraft:stone_bricks"
    },
    {
      "x": 15,
      "y": 0,
      "z": 12,
      "block": "minecraft:stone_bricks"
    },
    {
      "x": 16,
      "y": 0,
      "z": 12,
      "block": "minecraft:stone_bricks"
    },
    {
      "x": 17,
      "y": 0,
      "z": 12,
      "block": "minecraft:stone_bricks"
    },
    {
      "x": 18,
      "y": 0,
      "z": 12,
      "block": "minecraft:stone_bricks"
    },
    {
      "x": 10,
      "y": 1,
      "z": 0,
      "block": "minecraft:chiseled_stone_bricks"
    },
    {
      "x": 20,
      "y": 1,
      "z": 0,
      "block": "minecraft:chiseled_stone_bricks"
    },
    {
      "x": 1,
      "y": 1,
      "z": 1,
      "block": "minecraft:chiseled_stone_bricks"
    },
    {
      "x": 2,
      "y": 1,
      "z": 1,
      "block": "minecraft:stone_bricks"
    },
    {
      "x": 3,
      "y": 1,
      "z": 1,
      "block": "minecraft:stone_bricks"
    },
    {
      "x": 4,
      "y": 1,
      "z": 1,
      "block": "minecraft:stone_bricks"
    },
    {
      "x": 5,
      "y": 1,
      "z": 1,
      "block": "minecraft:stone_bricks"
    },
    {
      "x": 6,
      "y": 1,
      "z": 1,
      "block": "minecraft:stone_bricks"
    },
    {
      "x": 7,
      "y": 1,
      "z": 1,
      "block": "minecraft:chiseled_stone_bricks"
    },
    {
      "x": 8,
      "y": 1,
      "z": 1,
      "block": "minecraft:chiseled_stone_bricks"
    },
    {
      "x": 9,
      "y": 1,
      "z": 1,
      "block": "minecraft:stone_bricks"
    },
    {
      "x": 10,
      "y": 1,
      "z": 1,
      "block": "minecraft:chiseled_stone_bricks"
    },
    {
      "x": 11,
      "y": 1,
      "z": 1,
      "block": "minecraft:stone_bricks"
    },
    {
      "x": 19,
      "y": 1,
      "z": 1,
      "block": "minecraft:stone_bricks"
    },
    {
      "x": 20,
      "y": 1,
      "z": 1,
      "block": "minecraft:chiseled_stone_bricks"
    },
    {
      "x": 21,
      "y": 1,
      "z": 1,
      "block": "minecraft:stone_bricks"
    },
    {
      "x": 22,
      "y": 1,
      "z": 1,
      "block": "minecraft:chiseled_stone_bricks"
    },
    {
      "x": 23,
      "y": 1,
      "z": 1,
      "block": "minecraft:chiseled_stone_bricks"
    },
    {
      "x": 24,
      "y": 1,
      "z": 1,
      "block": "minecraft:stone_bricks"
    },
    {
      "x": 25,
      "y": 1,
      "z": 1,
      "block": "minecraft:stone_bricks"
    },
    {
      "x": 26,
      "y": 1,
      "z": 1,
      "block": "minecraft:stone_bricks"
    },
    {
      "x": 27,
      "y": 1,
      "z": 1,
      "block": "minecraft:stone_bricks"
    },
    {
      "x": 28,
      "y": 1,
      "z": 1,
      "block": "minecraft:stone_bricks"
    },
    {
      "x": 29,
      "y": 1,
      "z": 1,
      "block": "minecraft:chiseled_stone_bricks"
    },
    {
      "x": 1,
      "y": 1,
      "z": 2,
      "block": "minecraft:stone_bricks"
    },
    {
      "x": 7,
      "y": 1,
      "z": 2,
      "block": "minecraft:stone_bricks"
    },
    {
      "x": 8,
      "y": 1,
      "z": 2,
      "block": "minecraft:stone_bricks"
    },
    {
      "x": 22,
      "y": 1,
      "z": 2,
      "block": "minecraft:stone_bricks"
    },
    {
      "x": 23,
      "y": 1,
      "z": 2,
      "block": "minecraft:stone_bricks"
    },
    {
      "x": 29,
      "y": 1,
      "z": 2,
      "block": "minecraft:stone_bricks"
    },
    {
      "x": 1,
      "y": 1,
      "z": 3,
      "block": "minecraft:stone_bricks"
    },
    {
      "x": 7,
      "y": 1,
      "z": 3,
      "block": "minecraft:stone_bricks"
    },
    {
      "x": 8,
      "y": 1,
      "z": 3,
      "block": "minecraft:stone_bricks"
    },
    {
      "x": 13,
      "y": 1,
      "z": 3,
      "block": "minecraft:iron_bars"
    },
    {
      "x": 15,
      "y": 1,
      "z": 3,
      "block": "minecraft:iron_bars"
    },
    {
      "x": 17,
      "y": 1,
      "z": 3,
      "block": "minecraft:iron_bars"
    },
    {
      "x": 22,
      "y": 1,
      "z": 3,
      "block": "minecraft:stone_bricks"
    },
    {
      "x": 23,
      "y": 1,
      "z": 3,
      "block": "minecraft:stone_bricks"
    },
    {
      "x": 29,
      "y": 1,
      "z": 3,
      "block": "minecraft:stone_bricks"
    },
    {
      "x": 1,
      "y": 1,
      "z": 4,
      "block": "minecraft:stone_bricks"
    },
    {
      "x": 7,
      "y": 1,
      "z": 4,
      "block": "minecraft:stone_bricks"
    },
    {
      "x": 8,
      "y": 1,
      "z": 4,
      "block": "minecraft:stone_bricks"
    },
    {
      "x": 22,
      "y": 1,
      "z": 4,
      "block": "minecraft:stone_bricks"
    },
    {
      "x": 23,
      "y": 1,
      "z": 4,
      "block": "minecraft:stone_bricks"
    },
    {
      "x": 29,
      "y": 1,
      "z": 4,
      "block": "minecraft:stone_bricks"
    },
    {
      "x": 1,
      "y": 1,
      "z": 5,
      "block": "minecraft:stone_bricks"
    },
    {
      "x": 7,
      "y": 1,
      "z": 5,
      "block": "minecraft:stone_bricks"
    },
    {
      "x": 8,
      "y": 1,
      "z": 5,
      "block": "minecraft:stone_bricks"
    },
    {
      "x": 22,
      "y": 1,
      "z": 5,
      "block": "minecraft:stone_bricks"
    },
    {
      "x": 23,
      "y": 1,
      "z": 5,
      "block": "minecraft:stone_bricks"
    },
    {
      "x": 29,
      "y": 1,
      "z": 5,
      "block": "minecraft:stone_bricks"
    },
    {
      "x": 0,
      "y": 1,
      "z": 6,
      "block": "minecraft:stone_bricks"
    },
    {
      "x": 1,
      "y": 1,
      "z": 6,
      "block": "minecraft:stone_bricks"
    },
    {
      "x": 2,
      "y": 1,
      "z": 6,
      "block": "minecraft:stone_bricks"
    },
    {
      "x": 3,
      "y": 1,
      "z": 6,
      "block": "minecraft:stone_bricks"
    },
    {
      "x": 4,
      "y": 1,
      "z": 6,
      "block": "minecraft:stone_bricks"
    },
    {
      "x": 5,
      "y": 1,
      "z": 6,
      "block": "minecraft:stone_bricks"
    },
    {
      "x": 6,
      "y": 1,
      "z": 6,
      "block": "minecraft:stone_bricks"
    },
    {
      "x": 7,
      "y": 1,
      "z": 6,
      "block": "minecraft:stone_bricks"
    },
    {
      "x": 8,
      "y": 1,
      "z": 6,
      "block": "minecraft:stone_bricks"
    },
    {
      "x": 22,
      "y": 1,
      "z": 6,
      "block": "minecraft:stone_bricks"
    },
    {
      "x": 23,
      "y": 1,
      "z": 6,
      "block": "minecraft:stone_bricks"
    },
    {
      "x": 24,
      "y": 1,
      "z": 6,
      "block": "minecraft:stone_bricks"
    },
    {
      "x": 25,
      "y": 1,
      "z": 6,
      "block": "minecraft:stone_bricks"
    },
    {
      "x": 26,
      "y": 1,
      "z": 6,
      "block": "minecraft:stone_bricks"
    },
    {
      "x": 27,
      "y": 1,
      "z": 6,
      "block": "minecraft:stone_bricks"
    },
    {
      "x": 28,
      "y": 1,
      "z": 6,
      "block": "minecraft:stone_bricks"
    },
    {
      "x": 29,
      "y": 1,
      "z": 6,
      "block": "minecraft:stone_bricks"
    },
    {
      "x": 30,
      "y": 1,
      "z": 6,
      "block": "minecraft:stone_bricks"
    },
    {
      "x": 1,
      "y": 1,
      "z": 7,
      "block": "minecraft:stone_bricks"
    },
    {
      "x": 7,
      "y": 1,
      "z": 7,
      "block": "minecraft:stone_bricks"
    },
    {
      "x": 8,
      "y": 1,
      "z": 7,
      "block": "minecraft:stone_bricks"
    },
    {
      "x": 22,
      "y": 1,
      "z": 7,
      "block": "minecraft:stone_bricks"
    },
    {
      "x": 23,
      "y": 1,
      "z": 7,
      "block": "minecraft:stone_bricks"
    },
    {
      "x": 29,
      "y": 1,
      "z": 7,
      "block": "minecraft:stone_bricks"
    },
    {
      "x": 1,
      "y": 1,
      "z": 8,
      "block": "minecraft:stone_bricks"
    },
    {
      "x": 7,
      "y": 1,
      "z": 8,
      "block": "minecraft:stone_bricks"
    },
    {
      "x": 8,
      "y": 1,
      "z": 8,
      "block": "minecraft:stone_bricks"
    },
    {
      "x": 22,
      "y": 1,
      "z": 8,
      "block": "minecraft:stone_bricks"
    },
    {
      "x": 23,
      "y": 1,
      "z": 8,
      "block": "minecraft:stone_bricks"
    },
    {
      "x": 29,
      "y": 1,
      "z": 8,
      "block": "minecraft:stone_bricks"
    },
    {
      "x": 1,
      "y": 1,
      "z": 9,
      "block": "minecraft:stone_bricks"
    },
    {
      "x": 7,
      "y": 1,
      "z": 9,
      "block": "minecraft:stone_bricks"
    },
    {
      "x": 8,
      "y": 1,
      "z": 9,
      "block": "minecraft:stone_bricks"
    },
    {
      "x": 22,
      "y": 1,
      "z": 9,
      "block": "minecraft:stone_bricks"
    },
    {
      "x": 23,
      "y": 1,
      "z": 9,
      "block": "minecraft:stone_bricks"
    },
    {
      "x": 29,
      "y": 1,
      "z": 9,
      "block": "minecraft:stone_bricks"
    },
    {
      "x": 1,
      "y": 1,
      "z": 10,
      "block": "minecraft:stone_bricks"
    },
    {
      "x": 7,
      "y": 1,
      "z": 10,
      "block": "minecraft:stone_bricks"
    },
    {
      "x": 8,
      "y": 1,
      "z": 10,
      "block": "minecraft:stone_bricks"
    },
    {
      "x": 22,
      "y": 1,
      "z": 10,
      "block": "minecraft:stone_bricks"
    },
    {
      "x": 23,
      "y": 1,
      "z": 10,
      "block": "minecraft:stone_bricks"
    },
    {
      "x": 29,
      "y": 1,
      "z": 10,
      "block": "minecraft:stone_bricks"
    },
    {
      "x": 1,
      "y": 1,
      "z": 11,
      "block": "minecraft:chiseled_stone_bricks"
    },
    {
      "x": 2,
      "y": 1,
      "z": 11,
      "block": "minecraft:stone_bricks"
    },
    {
      "x": 3,
      "y": 1,
      "z": 11,
      "block": "minecraft:stone_bricks"
    },
    {
      "x": 4,
      "y": 1,
      "z": 11,
      "block": "minecraft:stone_bricks"
    },
    {
      "x": 5,
      "y": 1,
      "z": 11,
      "block": "minecraft:stone_bricks"
    },
    {
      "x": 6,
      "y": 1,
      "z": 11,
      "block": "minecraft:stone_bricks"
    },
    {
      "x": 7,
      "y": 1,
      "z": 11,
      "block": "minecraft:chiseled_stone_bricks"
    },
    {
      "x": 8,
      "y": 1,
      "z": 11,
      "block": "minecraft:chiseled_stone_bricks"
    },
    {
      "x": 9,
      "y": 1,
      "z": 11,
      "block": "minecraft:stone_bricks"
    },
    {
      "x": 10,
      "y": 1,
      "z": 11,
      "block": "minecraft:chiseled_stone_bricks"
    },
    {
      "x": 11,
      "y": 1,
      "z": 11,
      "block": "minecraft:stone_bricks"
    },
    {
      "x": 19,
      "y": 1,
      "z": 11,
      "block": "minecraft:stone_bricks"
    },
    {
      "x": 20,
      "y": 1,
      "z": 11,
      "block": "minecraft:chiseled_stone_bricks"
    },
    {
      "x": 21,
      "y": 1,
      "z": 11,
      "block": "minecraft:stone_bricks"
    },
    {
      "x": 22,
      "y": 1,
      "z": 11,
      "block": "minecraft:chiseled_stone_bricks"
    },
    {
      "x": 23,
      "y": 1,
      "z": 11,
      "block": "minecraft:chiseled_stone_bricks"
    },
    {
      "x": 24,
      "y": 1,
      "z": 11,
      "block": "minecraft:stone_bricks"
    },
    {
      "x": 25,
      "y": 1,
      "z": 11,
      "block": "minecraft:stone_bricks"
    },
    {
      "x": 26,
      "y": 1,
      "z": 11,
      "block": "minecraft:stone_bricks"
    },
    {
      "x": 27,
      "y": 1,
      "z": 11,
      "block": "minecraft:stone_bricks"
    },
    {
      "x": 28,
      "y": 1,
      "z": 11,
      "block": "minecraft:stone_bricks"
    },
    {
      "x": 29,
      "y": 1,
      "z": 11,
      "block": "minecraft:chiseled_stone_bricks"
    },
    {
      "x": 10,
      "y": 1,
      "z": 12,
      "block": "minecraft:chiseled_stone_bricks"
    },
    {
      "x": 20,
      "y": 1,
      "z": 12,
      "block": "minecraft:chiseled_stone_bricks"
    },
    {
      "x": 10,
      "y": 2,
      "z": 0,
      "block": "minecraft:chiseled_stone_bricks"
    },
    {
      "x": 20,
      "y": 2,
      "z": 0,
      "block": "minecraft:chiseled_stone_bricks"
    },
    {
      "x": 1,
      "y": 2,
      "z": 1,
      "block": "minecraft:chiseled_stone_bricks"
    },
    {
      "x": 2,
      "y": 2,
      "z": 1,
      "block": "minecraft:stone_bricks"
    },
    {
      "x": 3,
      "y": 2,
      "z": 1,
      "block": "minecraft:stone_bricks"
    },
    {
      "x": 4,
      "y": 2,
      "z": 1,
      "block": "minecraft:stone_bricks"
    },
    {
      "x": 5,
      "y": 2,
      "z": 1,
      "block": "minecraft:stone_bricks"
    },
    {
      "x": 6,
      "y": 2,
      "z": 1,
      "block": "minecraft:stone_bricks"
    },
    {
      "x": 7,
      "y": 2,
      "z": 1,
      "block": "minecraft:chiseled_stone_bricks"
    },
    {
      "x": 8,
      "y": 2,
      "z": 1,
      "block": "minecraft:chiseled_stone_bricks"
    },
    {
      "x": 9,
      "y": 2,
      "z": 1,
      "block": "minecraft:stone_bricks"
    },
    {
      "x": 10,
      "y": 2,
      "z": 1,
      "block": "minecraft:chiseled_stone_bricks"
    },
    {
      "x": 11,
      "y": 2,
      "z": 1,
      "block": "minecraft:stone_bricks"
    },
    {
      "x": 19,
      "y": 2,
      "z": 1,
      "block": "minecraft:stone_bricks"
    },
    {
      "x": 20,
      "y": 2,
      "z": 1,
      "block": "minecraft:chiseled_stone_bricks"
    },
    {
      "x": 21,
      "y": 2,
      "z": 1,
      "block": "minecraft:stone_bricks"
    },
    {
      "x": 22,
      "y": 2,
      "z": 1,
      "block": "minecraft:chiseled_stone_bricks"
    },
    {
      "x": 23,
      "y": 2,
      "z": 1,
      "block": "minecraft:chiseled_stone_bricks"
    },
    {
      "x": 24,
      "y": 2,
      "z": 1,
      "block": "minecraft:stone_bricks"
    },
    {
      "x": 25,
      "y": 2,
      "z": 1,
      "block": "minecraft:stone_bricks"
    },
    {
      "x": 26,
      "y": 2,
      "z": 1,
      "block": "minecraft:stone_bricks"
    },
    {
      "x": 27,
      "y": 2,
      "z": 1,
      "block": "minecraft:stone_bricks"
    },
    {
      "x": 28,
      "y": 2,
      "z": 1,
      "block": "minecraft:stone_bricks"
    },
    {
      "x": 29,
      "y": 2,
      "z": 1,
      "block": "minecraft:chiseled_stone_bricks"
    },
    {
      "x": 1,
      "y": 2,
      "z": 2,
      "block": "minecraft:stone_bricks"
    },
    {
      "x": 7,
      "y": 2,
      "z": 2,
      "block": "minecraft:stone_bricks"
    },
    {
      "x": 8,
      "y": 2,
      "z": 2,
      "block": "minecraft:stone_bricks"
    },
    {
      "x": 22,
      "y": 2,
      "z": 2,
      "block": "minecraft:stone_bricks"
    },
    {
      "x": 23,
      "y": 2,
      "z": 2,
      "block": "minecraft:stone_bricks"
    },
    {
      "x": 29,
      "y": 2,
      "z": 2,
      "block": "minecraft:stone_bricks"
    },
    {
      "x": 1,
      "y": 2,
      "z": 3,
      "block": "minecraft:stone_bricks"
    },
    {
      "x": 7,
      "y": 2,
      "z": 3,
      "block": "minecraft:stone_bricks"
    },
    {
      "x": 8,
      "y": 2,
      "z": 3,
      "block": "minecraft:stone_bricks"
    },
    {
      "x": 13,
      "y": 2,
      "z": 3,
      "block": "minecraft:iron_bars"
    },
    {
      "x": 15,
      "y": 2,
      "z": 3,
      "block": "minecraft:iron_bars"
    },
    {
      "x": 17,
      "y": 2,
      "z": 3,
      "block": "minecraft:iron_bars"
    },
    {
      "x": 22,
      "y": 2,
      "z": 3,
      "block": "minecraft:stone_bricks"
    },
    {
      "x": 23,
      "y": 2,
      "z": 3,
      "block": "minecraft:stone_bricks"
    },
    {
      "x": 29,
      "y": 2,
      "z": 3,
      "block": "minecraft:stone_bricks"
    },
    {
      "x": 1,
      "y": 2,
      "z": 4,
      "block": "minecraft:stone_bricks"
    },
    {
      "x": 7,
      "y": 2,
      "z": 4,
      "block": "minecraft:stone_bricks"
    },
    {
      "x": 8,
      "y": 2,
      "z": 4,
      "block": "minecraft:stone_bricks"
    },
    {
      "x": 22,
      "y": 2,
      "z": 4,
      "block": "minecraft:stone_bricks"
    },
    {
      "x": 23,
      "y": 2,
      "z": 4,
      "block": "minecraft:stone_bricks"
    },
    {
      "x": 29,
      "y": 2,
      "z": 4,
      "block": "minecraft:stone_bricks"
    },
    {
      "x": 1,
      "y": 2,
      "z": 5,
      "block": "minecraft:stone_bricks"
    },
    {
      "x": 7,
      "y": 2,
      "z": 5,
      "block": "minecraft:stone_bricks"
    },
    {
      "x": 8,
      "y": 2,
      "z": 5,
      "block": "minecraft:stone_bricks"
    },
    {
      "x": 22,
      "y": 2,
      "z": 5,
      "block": "minecraft:stone_bricks"
    },
    {
      "x": 23,
      "y": 2,
      "z": 5,
      "block": "minecraft:stone_bricks"
    },
    {
      "x": 29,
      "y": 2,
      "z": 5,
      "block": "minecraft:stone_bricks"
    },
    {
      "x": 0,
      "y": 2,
      "z": 6,
      "block": "minecraft:stone_bricks"
    },
    {
      "x": 1,
      "y": 2,
      "z": 6,
      "block": "minecraft:stone_bricks"
    },
    {
      "x": 2,
      "y": 2,
      "z": 6,
      "block": "minecraft:stone_bricks"
    },
    {
      "x": 3,
      "y": 2,
      "z": 6,
      "block": "minecraft:stone_bricks"
    },
    {
      "x": 4,
      "y": 2,
      "z": 6,
      "block": "minecraft:stone_bricks"
    },
    {
      "x": 5,
      "y": 2,
      "z": 6,
      "block": "minecraft:stone_bricks"
    },
    {
      "x": 6,
      "y": 2,
      "z": 6,
      "block": "minecraft:stone_bricks"
    },
    {
      "x": 7,
      "y": 2,
      "z": 6,
      "block": "minecraft:stone_bricks"
    },
    {
      "x": 8,
      "y": 2,
      "z": 6,
      "block": "minecraft:stone_bricks"
    },
    {
      "x": 22,
      "y": 2,
      "z": 6,
      "block": "minecraft:stone_bricks"
    },
    {
      "x": 23,
      "y": 2,
      "z": 6,
      "block": "minecraft:stone_bricks"
    },
    {
      "x": 24,
      "y": 2,
      "z": 6,
      "block": "minecraft:stone_bricks"
    },
    {
      "x": 25,
      "y": 2,
      "z": 6,
      "block": "minecraft:stone_bricks"
    },
    {
      "x": 26,
      "y": 2,
      "z": 6,
      "block": "minecraft:stone_bricks"
    },
    {
      "x": 27,
      "y": 2,
      "z": 6,
      "block": "minecraft:stone_bricks"
    },
    {
      "x": 28,
      "y": 2,
      "z": 6,
      "block": "minecraft:stone_bricks"
    },
    {
      "x": 29,
      "y": 2,
      "z": 6,
      "block": "minecraft:stone_bricks"
    },
    {
      "x": 30,
      "y": 2,
      "z": 6,
      "block": "minecraft:stone_bricks"
    },
    {
      "x": 1,
      "y": 2,
      "z": 7,
      "block": "minecraft:stone_bricks"
    },
    {
      "x": 7,
      "y": 2,
      "z": 7,
      "block": "minecraft:stone_bricks"
    },
    {
      "x": 8,
      "y": 2,
      "z": 7,
      "block": "minecraft:stone_bricks"
    },
    {
      "x": 22,
      "y": 2,
      "z": 7,
      "block": "minecraft:stone_bricks"
    },
    {
      "x": 23,
      "y": 2,
      "z": 7,
      "block": "minecraft:stone_bricks"
    },
    {
      "x": 29,
      "y": 2,
      "z": 7,
      "block": "minecraft:stone_bricks"
    },
    {
      "x": 1,
      "y": 2,
      "z": 8,
      "block": "minecraft:stone_bricks"
    },
    {
      "x": 7,
      "y": 2,
      "z": 8,
      "block": "minecraft:stone_bricks"
    },
    {
      "x": 8,
      "y": 2,
      "z": 8,
      "block": "minecraft:stone_bricks"
    },
    {
      "x": 22,
      "y": 2,
      "z": 8,
      "block": "minecraft:stone_bricks"
    },
    {
      "x": 23,
      "y": 2,
      "z": 8,
      "block": "minecraft:stone_bricks"
    },
    {
      "x": 29,
      "y": 2,
      "z": 8,
      "block": "minecraft:stone_bricks"
    },
    {
      "x": 1,
      "y": 2,
      "z": 9,
      "block": "minecraft:stone_bricks"
    },
    {
      "x": 7,
      "y": 2,
      "z": 9,
      "block": "minecraft:stone_bricks"
    },
    {
      "x": 8,
      "y": 2,
      "z": 9,
      "block": "minecraft:stone_bricks"
    },
    {
      "x": 22,
      "y": 2,
      "z": 9,
      "block": "minecraft:stone_bricks"
    },
    {
      "x": 23,
      "y": 2,
      "z": 9,
      "block": "minecraft:stone_bricks"
    },
    {
      "x": 29,
      "y": 2,
      "z": 9,
      "block": "minecraft:stone_bricks"
    },
    {
      "x": 1,
      "y": 2,
      "z": 10,
      "block": "minecraft:stone_bricks"
    },
    {
      "x": 7,
      "y": 2,
      "z": 10,
      "block": "minecraft:stone_bricks"
    },
    {
      "x": 8,
      "y": 2,
      "z": 10,
      "block": "minecraft:stone_bricks"
    },
    {
      "x": 22,
      "y": 2,
      "z": 10,
      "block": "minecraft:stone_bricks"
    },
    {
      "x": 23,
      "y": 2,
      "z": 10,
      "block": "minecraft:stone_bricks"
    },
    {
      "x": 29,
      "y": 2,
      "z": 10,
      "block": "minecraft:stone_bricks"
    },
    {
      "x": 1,
      "y": 2,
      "z": 11,
      "block": "minecraft:chiseled_stone_bricks"
    },
    {
      "x": 2,
      "y": 2,
      "z": 11,
      "block": "minecraft:stone_bricks"
    },
    {
      "x": 3,
      "y": 2,
      "z": 11,
      "block": "minecraft:stone_bricks"
    },
    {
      "x": 4,
      "y": 2,
      "z": 11,
      "block": "minecraft:stone_bricks"
    },
    {
      "x": 5,
      "y": 2,
      "z": 11,
      "block": "minecraft:stone_bricks"
    },
    {
      "x": 6,
      "y": 2,
      "z": 11,
      "block": "minecraft:stone_bricks"
    },
    {
      "x": 7,
      "y": 2,
      "z": 11,
      "block": "minecraft:chiseled_stone_bricks"
    },
    {
      "x": 8,
      "y": 2,
      "z": 11,
      "block": "minecraft:chiseled_stone_bricks"
    },
    {
      "x": 9,
      "y": 2,
      "z": 11,
      "block": "minecraft:stone_bricks"
    },
    {
      "x": 10,
      "y": 2,
      "z": 11,
      "block": "minecraft:chiseled_stone_bricks"
    },
    {
      "x": 11,
      "y": 2,
      "z": 11,
      "block": "minecraft:stone_bricks"
    },
    {
      "x": 19,
      "y": 2,
      "z": 11,
      "block": "minecraft:stone_bricks"
    },
    {
      "x": 20,
      "y": 2,
      "z": 11,
      "block": "minecraft:chiseled_stone_bricks"
    },
    {
      "x": 21,
      "y": 2,
      "z": 11,
      "block": "minecraft:stone_bricks"
    },
    {
      "x": 22,
      "y": 2,
      "z": 11,
      "block": "minecraft:chiseled_stone_bricks"
    },
    {
      "x": 23,
      "y": 2,
      "z": 11,
      "block": "minecraft:chiseled_stone_bricks"
    },
    {
      "x": 24,
      "y": 2,
      "z": 11,
      "block": "minecraft:stone_bricks"
    },
    {
      "x": 25,
      "y": 2,
      "z": 11,
      "block": "minecraft:stone_bricks"
    },
    {
      "x": 26,
      "y": 2,
      "z": 11,
      "block": "minecraft:stone_bricks"
    },
    {
      "x": 27,
      "y": 2,
      "z": 11,
      "block": "minecraft:stone_bricks"
    },
    {
      "x": 28,
      "y": 2,
      "z": 11,
      "block": "minecraft:stone_bricks"
    },
    {
      "x": 29,
      "y": 2,
      "z": 11,
      "block": "minecraft:chiseled_stone_bricks"
    },
    {
      "x": 10,
      "y": 2,
      "z": 12,
      "block": "minecraft:chiseled_stone_bricks"
    },
    {
      "x": 20,
      "y": 2,
      "z": 12,
      "block": "minecraft:chiseled_stone_bricks"
    },
    {
      "x": 10,
      "y": 3,
      "z": 0,
      "block": "minecraft:chiseled_stone_bricks"
    },
    {
      "x": 20,
      "y": 3,
      "z": 0,
      "block": "minecraft:chiseled_stone_bricks"
    },
    {
      "x": 1,
      "y": 3,
      "z": 1,
      "block": "minecraft:chiseled_stone_bricks"
    },
    {
      "x": 2,
      "y": 3,
      "z": 1,
      "block": "minecraft:stone_bricks"
    },
    {
      "x": 3,
      "y": 3,
      "z": 1,
      "block": "minecraft:cracked_stone_bricks"
    },
    {
      "x": 4,
      "y": 3,
      "z": 1,
      "block": "minecraft:stone_bricks"
    },
    {
      "x": 5,
      "y": 3,
      "z": 1,
      "block": "minecraft:stone_bricks"
    },
    {
      "x": 6,
      "y": 3,
      "z": 1,
      "block": "minecraft:stone_bricks"
    },
    {
      "x": 7,
      "y": 3,
      "z": 1,
      "block": "minecraft:chiseled_stone_bricks"
    },
    {
      "x": 8,
      "y": 3,
      "z": 1,
      "block": "minecraft:chiseled_stone_bricks"
    },
    {
      "x": 9,
      "y": 3,
      "z": 1,
      "block": "minecraft:stone_bricks"
    },
    {
      "x": 10,
      "y": 3,
      "z": 1,
      "block": "minecraft:chiseled_stone_bricks"
    },
    {
      "x": 11,
      "y": 3,
      "z": 1,
      "block": "minecraft:stone_bricks"
    },
    {
      "x": 19,
      "y": 3,
      "z": 1,
      "block": "minecraft:stone_bricks"
    },
    {
      "x": 20,
      "y": 3,
      "z": 1,
      "block": "minecraft:chiseled_stone_bricks"
    },
    {
      "x": 21,
      "y": 3,
      "z": 1,
      "block": "minecraft:stone_bricks"
    },
    {
      "x": 22,
      "y": 3,
      "z": 1,
      "block": "minecraft:chiseled_stone_bricks"
    },
    {
      "x": 23,
      "y": 3,
      "z": 1,
      "block": "minecraft:chiseled_stone_bricks"
    },
    {
      "x": 24,
      "y": 3,
      "z": 1,
      "block": "minecraft:stone_bricks"
    },
    {
      "x": 25,
      "y": 3,
      "z": 1,
      "block": "minecraft:stone_bricks"
    },
    {
      "x": 26,
      "y": 3,
      "z": 1,
      "block": "minecraft:stone_bricks"
    },
    {
      "x": 27,
      "y": 3,
      "z": 1,
      "block": "minecraft:stone_bricks"
    },
    {
      "x": 28,
      "y": 3,
      "z": 1,
      "block": "minecraft:stone_bricks"
    },
    {
      "x": 29,
      "y": 3,
      "z": 1,
      "block": "minecraft:chiseled_stone_bricks"
    },
    {
      "x": 1,
      "y": 3,
      "z": 2,
      "block": "minecraft:stone_bricks"
    },
    {
      "x": 7,
      "y": 3,
      "z": 2,
      "block": "minecraft:stone_bricks"
    },
    {
      "x": 8,
      "y": 3,
      "z": 2,
      "block": "minecraft:stone_bricks"
    },
    {
      "x": 22,
      "y": 3,
      "z": 2,
      "block": "minecraft:stone_bricks"
    },
    {
      "x": 23,
      "y": 3,
      "z": 2,
      "block": "minecraft:stone_bricks"
    },
    {
      "x": 29,
      "y": 3,
      "z": 2,
      "block": "minecraft:stone_bricks"
    },
    {
      "x": 1,
      "y": 3,
      "z": 3,
      "block": "minecraft:stone_bricks"
    },
    {
      "x": 7,
      "y": 3,
      "z": 3,
      "block": "minecraft:stone_bricks"
    },
    {
      "x": 8,
      "y": 3,
      "z": 3,
      "block": "minecraft:stone_bricks"
    },
    {
      "x": 13,
      "y": 3,
      "z": 3,
      "block": "minecraft:iron_bars"
    },
    {
      "x": 15,
      "y": 3,
      "z": 3,
      "block": "minecraft:iron_bars"
    },
    {
      "x": 17,
      "y": 3,
      "z": 3,
      "block": "minecraft:iron_bars"
    },
    {
      "x": 22,
      "y": 3,
      "z": 3,
      "block": "minecraft:stone_bricks"
    },
    {
      "x": 23,
      "y": 3,
      "z": 3,
      "block": "minecraft:stone_bricks"
    },
    {
      "x": 29,
      "y": 3,
      "z": 3,
      "block": "minecraft:stone_bricks"
    },
    {
      "x": 1,
      "y": 3,
      "z": 4,
      "block": "minecraft:stone_bricks"
    },
    {
      "x": 7,
      "y": 3,
      "z": 4,
      "block": "minecraft:stone_bricks"
    },
    {
      "x": 8,
      "y": 3,
      "z": 4,
      "block": "minecraft:stone_bricks"
    },
    {
      "x": 22,
      "y": 3,
      "z": 4,
      "block": "minecraft:stone_bricks"
    },
    {
      "x": 23,
      "y": 3,
      "z": 4,
      "block": "minecraft:stone_bricks"
    },
    {
      "x": 29,
      "y": 3,
      "z": 4,
      "block": "minecraft:stone_bricks"
    },
    {
      "x": 1,
      "y": 3,
      "z": 5,
      "block": "minecraft:stone_bricks"
    },
    {
      "x": 7,
      "y": 3,
      "z": 5,
      "block": "minecraft:stone_bricks"
    },
    {
      "x": 8,
      "y": 3,
      "z": 5,
      "block": "minecraft:stone_bricks"
    },
    {
      "x": 22,
      "y": 3,
      "z": 5,
      "block": "minecraft:stone_bricks"
    },
    {
      "x": 23,
      "y": 3,
      "z": 5,
      "block": "minecraft:stone_bricks"
    },
    {
      "x": 29,
      "y": 3,
      "z": 5,
      "block": "minecraft:stone_bricks"
    },
    {
      "x": 0,
      "y": 3,
      "z": 6,
      "block": "minecraft:stone_bricks"
    },
    {
      "x": 1,
      "y": 3,
      "z": 6,
      "block": "minecraft:stone_bricks"
    },
    {
      "x": 2,
      "y": 3,
      "z": 6,
      "block": "minecraft:stone_bricks"
    },
    {
      "x": 3,
      "y": 3,
      "z": 6,
      "block": "minecraft:stone_bricks"
    },
    {
      "x": 4,
      "y": 3,
      "z": 6,
      "block": "minecraft:stone_bricks"
    },
    {
      "x": 5,
      "y": 3,
      "z": 6,
      "block": "minecraft:stone_bricks"
    },
    {
      "x": 6,
      "y": 3,
      "z": 6,
      "block": "minecraft:cracked_stone_bricks"
    },
    {
      "x": 7,
      "y": 3,
      "z": 6,
      "block": "minecraft:stone_bricks"
    },
    {
      "x": 8,
      "y": 3,
      "z": 6,
      "block": "minecraft:stone_bricks"
    },
    {
      "x": 22,
      "y": 3,
      "z": 6,
      "block": "minecraft:stone_bricks"
    },
    {
      "x": 23,
      "y": 3,
      "z": 6,
      "block": "minecraft:stone_bricks"
    },
    {
      "x": 24,
      "y": 3,
      "z": 6,
      "block": "minecraft:cracked_stone_bricks"
    },
    {
      "x": 25,
      "y": 3,
      "z": 6,
      "block": "minecraft:stone_bricks"
    },
    {
      "x": 26,
      "y": 3,
      "z": 6,
      "block": "minecraft:stone_bricks"
    },
    {
      "x": 27,
      "y": 3,
      "z": 6,
      "block": "minecraft:stone_bricks"
    },
    {
      "x": 28,
      "y": 3,
      "z": 6,
      "block": "minecraft:stone_bricks"
    },
    {
      "x": 29,
      "y": 3,
      "z": 6,
      "block": "minecraft:stone_bricks"
    },
    {
      "x": 30,
      "y": 3,
      "z": 6,
      "block": "minecraft:stone_bricks"
    },
    {
      "x": 1,
      "y": 3,
      "z": 7,
      "block": "minecraft:stone_bricks"
    },
    {
      "x": 7,
      "y": 3,
      "z": 7,
      "block": "minecraft:stone_bricks"
    },
    {
      "x": 8,
      "y": 3,
      "z": 7,
      "block": "minecraft:stone_bricks"
    },
    {
      "x": 22,
      "y": 3,
      "z": 7,
      "block": "minecraft:stone_bricks"
    },
    {
      "x": 23,
      "y": 3,
      "z": 7,
      "block": "minecraft:stone_bricks"
    },
    {
      "x": 29,
      "y": 3,
      "z": 7,
      "block": "minecraft:stone_bricks"
    },
    {
      "x": 1,
      "y": 3,
      "z": 8,
      "block": "minecraft:stone_bricks"
    },
    {
      "x": 7,
      "y": 3,
      "z": 8,
      "block": "minecraft:stone_bricks"
    },
    {
      "x": 8,
      "y": 3,
      "z": 8,
      "block": "minecraft:stone_bricks"
    },
    {
      "x": 22,
      "y": 3,
      "z": 8,
      "block": "minecraft:stone_bricks"
    },
    {
      "x": 23,
      "y": 3,
      "z": 8,
      "block": "minecraft:stone_bricks"
    },
    {
      "x": 29,
      "y": 3,
      "z": 8,
      "block": "minecraft:stone_bricks"
    },
    {
      "x": 1,
      "y": 3,
      "z": 9,
      "block": "minecraft:stone_bricks"
    },
    {
      "x": 7,
      "y": 3,
      "z": 9,
      "block": "minecraft:stone_bricks"
    },
    {
      "x": 8,
      "y": 3,
      "z": 9,
      "block": "minecraft:stone_bricks"
    },
    {
      "x": 22,
      "y": 3,
      "z": 9,
      "block": "minecraft:stone_bricks"
    },
    {
      "x": 23,
      "y": 3,
      "z": 9,
      "block": "minecraft:stone_bricks"
    },
    {
      "x": 29,
      "y": 3,
      "z": 9,
      "block": "minecraft:stone_bricks"
    },
    {
      "x": 1,
      "y": 3,
      "z": 10,
      "block": "minecraft:stone_bricks"
    },
    {
      "x": 7,
      "y": 3,
      "z": 10,
      "block": "minecraft:stone_bricks"
    },
    {
      "x": 8,
      "y": 3,
      "z": 10,
      "block": "minecraft:stone_bricks"
    },
    {
      "x": 22,
      "y": 3,
      "z": 10,
      "block": "minecraft:stone_bricks"
    },
    {
      "x": 23,
      "y": 3,
      "z": 10,
      "block": "minecraft:stone_bricks"
    },
    {
      "x": 29,
      "y": 3,
      "z": 10,
      "block": "minecraft:stone_bricks"
    },
    {
      "x": 1,
      "y": 3,
      "z": 11,
      "block": "minecraft:chiseled_stone_bricks"
    },
    {
      "x": 2,
      "y": 3,
      "z": 11,
      "block": "minecraft:stone_bricks"
    },
    {
      "x": 3,
      "y": 3,
      "z": 11,
      "block": "minecraft:stone_bricks"
    },
    {
      "x": 4,
      "y": 3,
      "z": 11,
      "block": "minecraft:stone_bricks"
    },
    {
      "x": 5,
      "y": 3,
      "z": 11,
      "block": "minecraft:stone_bricks"
    },
    {
      "x": 6,
      "y": 3,
      "z": 11,
      "block": "minecraft:stone_bricks"
    },
    {
      "x": 7,
      "y": 3,
      "z": 11,
      "block": "minecraft:chiseled_stone_bricks"
    },
    {
      "x": 8,
      "y": 3,
      "z": 11,
      "block": "minecraft:chiseled_stone_bricks"
    },
    {
      "x": 9,
      "y": 3,
      "z": 11,
      "block": "minecraft:stone_bricks"
    },
    {
      "x": 10,
      "y": 3,
      "z": 11,
      "block": "minecraft:chiseled_stone_bricks"
    },
    {
      "x": 11,
      "y": 3,
      "z": 11,
      "block": "minecraft:stone_bricks"
    },
    {
      "x": 19,
      "y": 3,
      "z": 11,
      "block": "minecraft:stone_bricks"
    },
    {
      "x": 20,
      "y": 3,
      "z": 11,
      "block": "minecraft:chiseled_stone_bricks"
    },
    {
      "x": 21,
      "y": 3,
      "z": 11,
      "block": "minecraft:stone_bricks"
    },
    {
      "x": 22,
      "y": 3,
      "z": 11,
      "block": "minecraft:chiseled_stone_bricks"
    },
    {
      "x": 23,
      "y": 3,
      "z": 11,
      "block": "minecraft:chiseled_stone_bricks"
    },
    {
      "x": 24,
      "y": 3,
      "z": 11,
      "block": "minecraft:stone_bricks"
    },
    {
      "x": 25,
      "y": 3,
      "z": 11,
      "block": "minecraft:stone_bricks"
    },
    {
      "x": 26,
      "y": 3,
      "z": 11,
      "block": "minecraft:stone_bricks"
    },
    {
      "x": 27,
      "y": 3,
      "z": 11,
      "block": "minecraft:cracked_stone_bricks"
    },
    {
      "x": 28,
      "y": 3,
      "z": 11,
      "block": "minecraft:stone_bricks"
    },
    {
      "x": 29,
      "y": 3,
      "z": 11,
      "block": "minecraft:chiseled_stone_bricks"
    },
    {
      "x": 10,
      "y": 3,
      "z": 12,
      "block": "minecraft:chiseled_stone_bricks"
    },
    {
      "x": 20,
      "y": 3,
      "z": 12,
      "block": "minecraft:chiseled_stone_bricks"
    },
    {
      "x": 10,
      "y": 4,
      "z": 0,
      "block": "minecraft:chiseled_stone_bricks"
    },
    {
      "x": 20,
      "y": 4,
      "z": 0,
      "block": "minecraft:chiseled_stone_bricks"
    },
    {
      "x": 1,
      "y": 4,
      "z": 1,
      "block": "minecraft:chiseled_stone_bricks"
    },
    {
      "x": 2,
      "y": 4,
      "z": 1,
      "block": "minecraft:stone_bricks"
    },
    {
      "x": 3,
      "y": 4,
      "z": 1,
      "block": "minecraft:mossy_stone_bricks"
    },
    {
      "x": 4,
      "y": 4,
      "z": 1,
      "block": "minecraft:iron_bars"
    },
    {
      "x": 5,
      "y": 4,
      "z": 1,
      "block": "minecraft:stone_bricks"
    },
    {
      "x": 6,
      "y": 4,
      "z": 1,
      "block": "minecraft:stone_bricks"
    },
    {
      "x": 7,
      "y": 4,
      "z": 1,
      "block": "minecraft:chiseled_stone_bricks"
    },
    {
      "x": 8,
      "y": 4,
      "z": 1,
      "block": "minecraft:chiseled_stone_bricks"
    },
    {
      "x": 9,
      "y": 4,
      "z": 1,
      "block": "minecraft:stone_bricks"
    },
    {
      "x": 10,
      "y": 4,
      "z": 1,
      "block": "minecraft:chiseled_stone_bricks"
    },
    {
      "x": 11,
      "y": 4,
      "z": 1,
      "block": "minecraft:stone_bricks"
    },
    {
      "x": 19,
      "y": 4,
      "z": 1,
      "block": "minecraft:stone_bricks"
    },
    {
      "x": 20,
      "y": 4,
      "z": 1,
      "block": "minecraft:chiseled_stone_bricks"
    },
    {
      "x": 21,
      "y": 4,
      "z": 1,
      "block": "minecraft:stone_bricks"
    },
    {
      "x": 22,
      "y": 4,
      "z": 1,
      "block": "minecraft:chiseled_stone_bricks"
    },
    {
      "x": 23,
      "y": 4,
      "z": 1,
      "block": "minecraft:chiseled_stone_bricks"
    },
    {
      "x": 24,
      "y": 4,
      "z": 1,
      "block": "minecraft:stone_bricks"
    },
    {
      "x": 25,
      "y": 4,
      "z": 1,
      "block": "minecraft:stone_bricks"
    },
    {
      "x": 26,
      "y": 4,
      "z": 1,
      "block": "minecraft:iron_bars"
    },
    {
      "x": 27,
      "y": 4,
      "z": 1,
      "block": "minecraft:stone_bricks"
    },
    {
      "x": 28,
      "y": 4,
      "z": 1,
      "block": "minecraft:stone_bricks"
    },
    {
      "x": 29,
      "y": 4,
      "z": 1,
      "block": "minecraft:chiseled_stone_bricks"
    },
    {
      "x": 1,
      "y": 4,
      "z": 2,
      "block": "minecraft:stone_bricks"
    },
    {
      "x": 7,
      "y": 4,
      "z": 2,
      "block": "minecraft:stone_bricks"
    },
    {
      "x": 8,
      "y": 4,
      "z": 2,
      "block": "minecraft:stone_bricks"
    },
    {
      "x": 22,
      "y": 4,
      "z": 2,
      "block": "minecraft:stone_bricks"
    },
    {
      "x": 23,
      "y": 4,
      "z": 2,
      "block": "minecraft:stone_bricks"
    },
    {
      "x": 29,
      "y": 4,
      "z": 2,
      "block": "minecraft:stone_bricks"
    },
    {
      "x": 1,
      "y": 4,
      "z": 3,
      "block": "minecraft:stone_bricks"
    },
    {
      "x": 7,
      "y": 4,
      "z": 3,
      "block": "minecraft:stone_bricks"
    },
    {
      "x": 8,
      "y": 4,
      "z": 3,
      "block": "minecraft:stone_bricks"
    },
    {
      "x": 13,
      "y": 4,
      "z": 3,
      "block": "minecraft:iron_bars"
    },
    {
      "x": 15,
      "y": 4,
      "z": 3,
      "block": "minecraft:iron_bars"
    },
    {
      "x": 17,
      "y": 4,
      "z": 3,
      "block": "minecraft:iron_bars"
    },
    {
      "x": 22,
      "y": 4,
      "z": 3,
      "block": "minecraft:stone_bricks"
    },
    {
      "x": 23,
      "y": 4,
      "z": 3,
      "block": "minecraft:stone_bricks"
    },
    {
      "x": 29,
      "y": 4,
      "z": 3,
      "block": "minecraft:stone_bricks"
    },
    {
      "x": 1,
      "y": 4,
      "z": 4,
      "block": "minecraft:stone_bricks"
    },
    {
      "x": 7,
      "y": 4,
      "z": 4,
      "block": "minecraft:stone_bricks"
    },
    {
      "x": 8,
      "y": 4,
      "z": 4,
      "block": "minecraft:stone_bricks"
    },
    {
      "x": 22,
      "y": 4,
      "z": 4,
      "block": "minecraft:stone_bricks"
    },
    {
      "x": 23,
      "y": 4,
      "z": 4,
      "block": "minecraft:stone_bricks"
    },
    {
      "x": 29,
      "y": 4,
      "z": 4,
      "block": "minecraft:stone_bricks"
    },
    {
      "x": 1,
      "y": 4,
      "z": 5,
      "block": "minecraft:stone_bricks"
    },
    {
      "x": 7,
      "y": 4,
      "z": 5,
      "block": "minecraft:stone_bricks"
    },
    {
      "x": 8,
      "y": 4,
      "z": 5,
      "block": "minecraft:stone_bricks"
    },
    {
      "x": 22,
      "y": 4,
      "z": 5,
      "block": "minecraft:stone_bricks"
    },
    {
      "x": 23,
      "y": 4,
      "z": 5,
      "block": "minecraft:stone_bricks"
    },
    {
      "x": 29,
      "y": 4,
      "z": 5,
      "block": "minecraft:stone_bricks"
    },
    {
      "x": 0,
      "y": 4,
      "z": 6,
      "block": "minecraft:stone_bricks"
    },
    {
      "x": 1,
      "y": 4,
      "z": 6,
      "block": "minecraft:stone_bricks"
    },
    {
      "x": 2,
      "y": 4,
      "z": 6,
      "block": "minecraft:stone_bricks"
    },
    {
      "x": 3,
      "y": 4,
      "z": 6,
      "block": "minecraft:stone_bricks"
    },
    {
      "x": 4,
      "y": 4,
      "z": 6,
      "block": "minecraft:stone_bricks"
    },
    {
      "x": 5,
      "y": 4,
      "z": 6,
      "block": "minecraft:stone_bricks"
    },
    {
      "x": 6,
      "y": 4,
      "z": 6,
      "block": "minecraft:mossy_stone_bricks"
    },
    {
      "x": 7,
      "y": 4,
      "z": 6,
      "block": "minecraft:stone_bricks"
    },
    {
      "x": 8,
      "y": 4,
      "z": 6,
      "block": "minecraft:stone_bricks"
    },
    {
      "x": 22,
      "y": 4,
      "z": 6,
      "block": "minecraft:stone_bricks"
    },
    {
      "x": 23,
      "y": 4,
      "z": 6,
      "block": "minecraft:stone_bricks"
    },
    {
      "x": 24,
      "y": 4,
      "z": 6,
      "block": "minecraft:mossy_stone_bricks"
    },
    {
      "x": 25,
      "y": 4,
      "z": 6,
      "block": "minecraft:stone_bricks"
    },
    {
      "x": 26,
      "y": 4,
      "z": 6,
      "block": "minecraft:stone_bricks"
    },
    {
      "x": 27,
      "y": 4,
      "z": 6,
      "block": "minecraft:stone_bricks"
    },
    {
      "x": 28,
      "y": 4,
      "z": 6,
      "block": "minecraft:stone_bricks"
    },
    {
      "x": 29,
      "y": 4,
      "z": 6,
      "block": "minecraft:stone_bricks"
    },
    {
      "x": 30,
      "y": 4,
      "z": 6,
      "block": "minecraft:stone_bricks"
    },
    {
      "x": 1,
      "y": 4,
      "z": 7,
      "block": "minecraft:stone_bricks"
    },
    {
      "x": 7,
      "y": 4,
      "z": 7,
      "block": "minecraft:stone_bricks"
    },
    {
      "x": 8,
      "y": 4,
      "z": 7,
      "block": "minecraft:stone_bricks"
    },
    {
      "x": 22,
      "y": 4,
      "z": 7,
      "block": "minecraft:stone_bricks"
    },
    {
      "x": 23,
      "y": 4,
      "z": 7,
      "block": "minecraft:stone_bricks"
    },
    {
      "x": 29,
      "y": 4,
      "z": 7,
      "block": "minecraft:stone_bricks"
    },
    {
      "x": 1,
      "y": 4,
      "z": 8,
      "block": "minecraft:stone_bricks"
    },
    {
      "x": 7,
      "y": 4,
      "z": 8,
      "block": "minecraft:stone_bricks"
    },
    {
      "x": 8,
      "y": 4,
      "z": 8,
      "block": "minecraft:stone_bricks"
    },
    {
      "x": 22,
      "y": 4,
      "z": 8,
      "block": "minecraft:stone_bricks"
    },
    {
      "x": 23,
      "y": 4,
      "z": 8,
      "block": "minecraft:stone_bricks"
    },
    {
      "x": 29,
      "y": 4,
      "z": 8,
      "block": "minecraft:stone_bricks"
    },
    {
      "x": 1,
      "y": 4,
      "z": 9,
      "block": "minecraft:stone_bricks"
    },
    {
      "x": 7,
      "y": 4,
      "z": 9,
      "block": "minecraft:stone_bricks"
    },
    {
      "x": 8,
      "y": 4,
      "z": 9,
      "block": "minecraft:stone_bricks"
    },
    {
      "x": 22,
      "y": 4,
      "z": 9,
      "block": "minecraft:stone_bricks"
    },
    {
      "x": 23,
      "y": 4,
      "z": 9,
      "block": "minecraft:stone_bricks"
    },
    {
      "x": 29,
      "y": 4,
      "z": 9,
      "block": "minecraft:stone_bricks"
    },
    {
      "x": 1,
      "y": 4,
      "z": 10,
      "block": "minecraft:stone_bricks"
    },
    {
      "x": 7,
      "y": 4,
      "z": 10,
      "block": "minecraft:stone_bricks"
    },
    {
      "x": 8,
      "y": 4,
      "z": 10,
      "block": "minecraft:stone_bricks"
    },
    {
      "x": 22,
      "y": 4,
      "z": 10,
      "block": "minecraft:stone_bricks"
    },
    {
      "x": 23,
      "y": 4,
      "z": 10,
      "block": "minecraft:stone_bricks"
    },
    {
      "x": 29,
      "y": 4,
      "z": 10,
      "block": "minecraft:stone_bricks"
    },
    {
      "x": 1,
      "y": 4,
      "z": 11,
      "block": "minecraft:chiseled_stone_bricks"
    },
    {
      "x": 2,
      "y": 4,
      "z": 11,
      "block": "minecraft:stone_bricks"
    },
    {
      "x": 3,
      "y": 4,
      "z": 11,
      "block": "minecraft:stone_bricks"
    },
    {
      "x": 4,
      "y": 4,
      "z": 11,
      "block": "minecraft:iron_bars"
    },
    {
      "x": 5,
      "y": 4,
      "z": 11,
      "block": "minecraft:stone_bricks"
    },
    {
      "x": 6,
      "y": 4,
      "z": 11,
      "block": "minecraft:stone_bricks"
    },
    {
      "x": 7,
      "y": 4,
      "z": 11,
      "block": "minecraft:chiseled_stone_bricks"
    },
    {
      "x": 8,
      "y": 4,
      "z": 11,
      "block": "minecraft:chiseled_stone_bricks"
    },
    {
      "x": 9,
      "y": 4,
      "z": 11,
      "block": "minecraft:stone_bricks"
    },
    {
      "x": 10,
      "y": 4,
      "z": 11,
      "block": "minecraft:chiseled_stone_bricks"
    },
    {
      "x": 11,
      "y": 4,
      "z": 11,
      "block": "minecraft:stone_bricks"
    },
    {
      "x": 19,
      "y": 4,
      "z": 11,
      "block": "minecraft:stone_bricks"
    },
    {
      "x": 20,
      "y": 4,
      "z": 11,
      "block": "minecraft:chiseled_stone_bricks"
    },
    {
      "x": 21,
      "y": 4,
      "z": 11,
      "block": "minecraft:stone_bricks"
    },
    {
      "x": 22,
      "y": 4,
      "z": 11,
      "block": "minecraft:chiseled_stone_bricks"
    },
    {
      "x": 23,
      "y": 4,
      "z": 11,
      "block": "minecraft:chiseled_stone_bricks"
    },
    {
      "x": 24,
      "y": 4,
      "z": 11,
      "block": "minecraft:stone_bricks"
    },
    {
      "x": 25,
      "y": 4,
      "z": 11,
      "block": "minecraft:stone_bricks"
    },
    {
      "x": 26,
      "y": 4,
      "z": 11,
      "block": "minecraft:iron_bars"
    },
    {
      "x": 27,
      "y": 4,
      "z": 11,
      "block": "minecraft:mossy_stone_bricks"
    },
    {
      "x": 28,
      "y": 4,
      "z": 11,
      "block": "minecraft:stone_bricks"
    },
    {
      "x": 29,
      "y": 4,
      "z": 11,
      "block": "minecraft:chiseled_stone_bricks"
    },
    {
      "x": 10,
      "y": 4,
      "z": 12,
      "block": "minecraft:chiseled_stone_bricks"
    },
    {
      "x": 20,
      "y": 4,
      "z": 12,
      "block": "minecraft:chiseled_stone_bricks"
    },
    {
      "x": 10,
      "y": 5,
      "z": 0,
      "block": "minecraft:chiseled_stone_bricks"
    },
    {
      "x": 15,
      "y": 5,
      "z": 0,
      "block": "minecraft:oak_wall_sign[facing=north,waterlogged=false]"
    },
    {
      "x": 20,
      "y": 5,
      "z": 0,
      "block": "minecraft:chiseled_stone_bricks"
    },
    {
      "x": 1,
      "y": 5,
      "z": 1,
      "block": "minecraft:chiseled_stone_bricks"
    },
    {
      "x": 2,
      "y": 5,
      "z": 1,
      "block": "minecraft:chiseled_stone_bricks"
    },
    {
      "x": 3,
      "y": 5,
      "z": 1,
      "block": "minecraft:chiseled_stone_bricks"
    },
    {
      "x": 4,
      "y": 5,
      "z": 1,
      "block": "minecraft:iron_bars"
    },
    {
      "x": 5,
      "y": 5,
      "z": 1,
      "block": "minecraft:chiseled_stone_bricks"
    },
    {
      "x": 6,
      "y": 5,
      "z": 1,
      "block": "minecraft:chiseled_stone_bricks"
    },
    {
      "x": 7,
      "y": 5,
      "z": 1,
      "block": "minecraft:chiseled_stone_bricks"
    },
    {
      "x": 8,
      "y": 5,
      "z": 1,
      "block": "minecraft:chiseled_stone_bricks"
    },
    {
      "x": 9,
      "y": 5,
      "z": 1,
      "block": "minecraft:stone_bricks"
    },
    {
      "x": 10,
      "y": 5,
      "z": 1,
      "block": "minecraft:chiseled_stone_bricks"
    },
    {
      "x": 11,
      "y": 5,
      "z": 1,
      "block": "minecraft:stone_bricks"
    },
    {
      "x": 19,
      "y": 5,
      "z": 1,
      "block": "minecraft:stone_bricks"
    },
    {
      "x": 20,
      "y": 5,
      "z": 1,
      "block": "minecraft:chiseled_stone_bricks"
    },
    {
      "x": 21,
      "y": 5,
      "z": 1,
      "block": "minecraft:stone_bricks"
    },
    {
      "x": 22,
      "y": 5,
      "z": 1,
      "block": "minecraft:chiseled_stone_bricks"
    },
    {
      "x": 23,
      "y": 5,
      "z": 1,
      "block": "minecraft:chiseled_stone_bricks"
    },
    {
      "x": 24,
      "y": 5,
      "z": 1,
      "block": "minecraft:chiseled_stone_bricks"
    },
    {
      "x": 25,
      "y": 5,
      "z": 1,
      "block": "minecraft:chiseled_stone_bricks"
    },
    {
      "x": 26,
      "y": 5,
      "z": 1,
      "block": "minecraft:iron_bars"
    },
    {
      "x": 27,
      "y": 5,
      "z": 1,
      "block": "minecraft:chiseled_stone_bricks"
    },
    {
      "x": 28,
      "y": 5,
      "z": 1,
      "block": "minecraft:chiseled_stone_bricks"
    },
    {
      "x": 29,
      "y": 5,
      "z": 1,
      "block": "minecraft:chiseled_stone_bricks"
    },
    {
      "x": 1,
      "y": 5,
      "z": 2,
      "block": "minecraft:chiseled_stone_bricks"
    },
    {
      "x": 7,
      "y": 5,
      "z": 2,
      "block": "minecraft:chiseled_stone_bricks"
    },
    {
      "x": 8,
      "y": 5,
      "z": 2,
      "block": "minecraft:stone_bricks"
    },
    {
      "x": 22,
      "y": 5,
      "z": 2,
      "block": "minecraft:stone_bricks"
    },
    {
      "x": 23,
      "y": 5,
      "z": 2,
      "block": "minecraft:chiseled_stone_bricks"
    },
    {
      "x": 29,
      "y": 5,
      "z": 2,
      "block": "minecraft:chiseled_stone_bricks"
    },
    {
      "x": 1,
      "y": 5,
      "z": 3,
      "block": "minecraft:chiseled_stone_bricks"
    },
    {
      "x": 7,
      "y": 5,
      "z": 3,
      "block": "minecraft:chiseled_stone_bricks"
    },
    {
      "x": 8,
      "y": 5,
      "z": 3,
      "block": "minecraft:stone_bricks"
    },
    {
      "x": 13,
      "y": 5,
      "z": 3,
      "block": "minecraft:iron_bars"
    },
    {
      "x": 15,
      "y": 5,
      "z": 3,
      "block": "minecraft:iron_bars"
    },
    {
      "x": 17,
      "y": 5,
      "z": 3,
      "block": "minecraft:iron_bars"
    },
    {
      "x": 22,
      "y": 5,
      "z": 3,
      "block": "minecraft:stone_bricks"
    },
    {
      "x": 23,
      "y": 5,
      "z": 3,
      "block": "minecraft:chiseled_stone_bricks"
    },
    {
      "x": 29,
      "y": 5,
      "z": 3,
      "block": "minecraft:chiseled_stone_bricks"
    },
    {
      "x": 1,
      "y": 5,
      "z": 4,
      "block": "minecraft:iron_bars"
    },
    {
      "x": 7,
      "y": 5,
      "z": 4,
      "block": "minecraft:chiseled_stone_bricks"
    },
    {
      "x": 8,
      "y": 5,
      "z": 4,
      "block": "minecraft:stone_bricks"
    },
    {
      "x": 22,
      "y": 5,
      "z": 4,
      "block": "minecraft:stone_bricks"
    },
    {
      "x": 23,
      "y": 5,
      "z": 4,
      "block": "minecraft:chiseled_stone_bricks"
    },
    {
      "x": 29,
      "y": 5,
      "z": 4,
      "block": "minecraft:iron_bars"
    },
    {
      "x": 1,
      "y": 5,
      "z": 5,
      "block": "minecraft:chiseled_stone_bricks"
    },
    {
      "x": 7,
      "y": 5,
      "z": 5,
      "block": "minecraft:chiseled_stone_bricks"
    },
    {
      "x": 8,
      "y": 5,
      "z": 5,
      "block": "minecraft:stone_bricks"
    },
    {
      "x": 22,
      "y": 5,
      "z": 5,
      "block": "minecraft:stone_bricks"
    },
    {
      "x": 23,
      "y": 5,
      "z": 5,
      "block": "minecraft:chiseled_stone_bricks"
    },
    {
      "x": 29,
      "y": 5,
      "z": 5,
      "block": "minecraft:chiseled_stone_bricks"
    },
    {
      "x": 0,
      "y": 5,
      "z": 6,
      "block": "minecraft:stone_bricks"
    },
    {
      "x": 1,
      "y": 5,
      "z": 6,
      "block": "minecraft:stone_bricks"
    },
    {
      "x": 2,
      "y": 5,
      "z": 6,
      "block": "minecraft:stone_bricks"
    },
    {
      "x": 3,
      "y": 5,
      "z": 6,
      "block": "minecraft:stone_bricks"
    },
    {
      "x": 4,
      "y": 5,
      "z": 6,
      "block": "minecraft:stone_bricks"
    },
    {
      "x": 5,
      "y": 5,
      "z": 6,
      "block": "minecraft:stone_bricks"
    },
    {
      "x": 6,
      "y": 5,
      "z": 6,
      "block": "minecraft:stone_bricks"
    },
    {
      "x": 7,
      "y": 5,
      "z": 6,
      "block": "minecraft:stone_bricks"
    },
    {
      "x": 8,
      "y": 5,
      "z": 6,
      "block": "minecraft:stone_bricks"
    },
    {
      "x": 22,
      "y": 5,
      "z": 6,
      "block": "minecraft:stone_bricks"
    },
    {
      "x": 23,
      "y": 5,
      "z": 6,
      "block": "minecraft:stone_bricks"
    },
    {
      "x": 24,
      "y": 5,
      "z": 6,
      "block": "minecraft:stone_bricks"
    },
    {
      "x": 25,
      "y": 5,
      "z": 6,
      "block": "minecraft:stone_bricks"
    },
    {
      "x": 26,
      "y": 5,
      "z": 6,
      "block": "minecraft:stone_bricks"
    },
    {
      "x": 27,
      "y": 5,
      "z": 6,
      "block": "minecraft:stone_bricks"
    },
    {
      "x": 28,
      "y": 5,
      "z": 6,
      "block": "minecraft:stone_bricks"
    },
    {
      "x": 29,
      "y": 5,
      "z": 6,
      "block": "minecraft:stone_bricks"
    },
    {
      "x": 30,
      "y": 5,
      "z": 6,
      "block": "minecraft:stone_bricks"
    },
    {
      "x": 1,
      "y": 5,
      "z": 7,
      "block": "minecraft:chiseled_stone_bricks"
    },
    {
      "x": 7,
      "y": 5,
      "z": 7,
      "block": "minecraft:chiseled_stone_bricks"
    },
    {
      "x": 8,
      "y": 5,
      "z": 7,
      "block": "minecraft:stone_bricks"
    },
    {
      "x": 22,
      "y": 5,
      "z": 7,
      "block": "minecraft:stone_bricks"
    },
    {
      "x": 23,
      "y": 5,
      "z": 7,
      "block": "minecraft:chiseled_stone_bricks"
    },
    {
      "x": 29,
      "y": 5,
      "z": 7,
      "block": "minecraft:chiseled_stone_bricks"
    },
    {
      "x": 1,
      "y": 5,
      "z": 8,
      "block": "minecraft:chiseled_stone_bricks"
    },
    {
      "x": 7,
      "y": 5,
      "z": 8,
      "block": "minecraft:chiseled_stone_bricks"
    },
    {
      "x": 8,
      "y": 5,
      "z": 8,
      "block": "minecraft:stone_bricks"
    },
    {
      "x": 22,
      "y": 5,
      "z": 8,
      "block": "minecraft:stone_bricks"
    },
    {
      "x": 23,
      "y": 5,
      "z": 8,
      "block": "minecraft:chiseled_stone_bricks"
    },
    {
      "x": 29,
      "y": 5,
      "z": 8,
      "block": "minecraft:chiseled_stone_bricks"
    },
    {
      "x": 1,
      "y": 5,
      "z": 9,
      "block": "minecraft:chiseled_stone_bricks"
    },
    {
      "x": 7,
      "y": 5,
      "z": 9,
      "block": "minecraft:chiseled_stone_bricks"
    },
    {
      "x": 8,
      "y": 5,
      "z": 9,
      "block": "minecraft:stone_bricks"
    },
    {
      "x": 22,
      "y": 5,
      "z": 9,
      "block": "minecraft:stone_bricks"
    },
    {
      "x": 23,
      "y": 5,
      "z": 9,
      "block": "minecraft:chiseled_stone_bricks"
    },
    {
      "x": 29,
      "y": 5,
      "z": 9,
      "block": "minecraft:chiseled_stone_bricks"
    },
    {
      "x": 1,
      "y": 5,
      "z": 10,
      "block": "minecraft:chiseled_stone_bricks"
    },
    {
      "x": 7,
      "y": 5,
      "z": 10,
      "block": "minecraft:chiseled_stone_bricks"
    },
    {
      "x": 8,
      "y": 5,
      "z": 10,
      "block": "minecraft:stone_bricks"
    },
    {
      "x": 22,
      "y": 5,
      "z": 10,
      "block": "minecraft:stone_bricks"
    },
    {
      "x": 23,
      "y": 5,
      "z": 10,
      "block": "minecraft:chiseled_stone_bricks"
    },
    {
      "x": 29,
      "y": 5,
      "z": 10,
      "block": "minecraft:chiseled_stone_bricks"
    },
    {
      "x": 1,
      "y": 5,
      "z": 11,
      "block": "minecraft:chiseled_stone_bricks"
    },
    {
      "x": 2,
      "y": 5,
      "z": 11,
      "block": "minecraft:chiseled_stone_bricks"
    },
    {
      "x": 3,
      "y": 5,
      "z": 11,
      "block": "minecraft:chiseled_stone_bricks"
    },
    {
      "x": 4,
      "y": 5,
      "z": 11,
      "block": "minecraft:iron_bars"
    },
    {
      "x": 5,
      "y": 5,
      "z": 11,
      "block": "minecraft:chiseled_stone_bricks"
    },
    {
      "x": 6,
      "y": 5,
      "z": 11,
      "block": "minecraft:chiseled_stone_bricks"
    },
    {
      "x": 7,
      "y": 5,
      "z": 11,
      "block": "minecraft:chiseled_stone_bricks"
    },
    {
      "x": 8,
      "y": 5,
      "z": 11,
      "block": "minecraft:chiseled_stone_bricks"
    },
    {
      "x": 9,
      "y": 5,
      "z": 11,
      "block": "minecraft:stone_bricks"
    },
    {
      "x": 10,
      "y": 5,
      "z": 11,
      "block": "minecraft:chiseled_stone_bricks"
    },
    {
      "x": 11,
      "y": 5,
      "z": 11,
      "block": "minecraft:stone_bricks"
    },
    {
      "x": 19,
      "y": 5,
      "z": 11,
      "block": "minecraft:stone_bricks"
    },
    {
      "x": 20,
      "y": 5,
      "z": 11,
      "block": "minecraft:chiseled_stone_bricks"
    },
    {
      "x": 21,
      "y": 5,
      "z": 11,
      "block": "minecraft:stone_bricks"
    },
    {
      "x": 22,
      "y": 5,
      "z": 11,
      "block": "minecraft:chiseled_stone_bricks"
    },
    {
      "x": 23,
      "y": 5,
      "z": 11,
      "block": "minecraft:chiseled_stone_bricks"
    },
    {
      "x": 24,
      "y": 5,
      "z": 11,
      "block": "minecraft:chiseled_stone_bricks"
    },
    {
      "x": 25,
      "y": 5,
      "z": 11,
      "block": "minecraft:chiseled_stone_bricks"
    },
    {
      "x": 26,
      "y": 5,
      "z": 11,
      "block": "minecraft:iron_bars"
    },
    {
      "x": 27,
      "y": 5,
      "z": 11,
      "block": "minecraft:chiseled_stone_bricks"
    },
    {
      "x": 28,
      "y": 5,
      "z": 11,
      "block": "minecraft:chiseled_stone_bricks"
    },
    {
      "x": 29,
      "y": 5,
      "z": 11,
      "block": "minecraft:chiseled_stone_bricks"
    },
    {
      "x": 10,
      "y": 5,
      "z": 12,
      "block": "minecraft:chiseled_stone_bricks"
    },
    {
      "x": 20,
      "y": 5,
      "z": 12,
      "block": "minecraft:chiseled_stone_bricks"
    },
    {
      "x": 10,
      "y": 6,
      "z": 0,
      "block": "minecraft:chiseled_stone_bricks"
    },
    {
      "x": 20,
      "y": 6,
      "z": 0,
      "block": "minecraft:chiseled_stone_bricks"
    },
    {
      "x": 1,
      "y": 6,
      "z": 1,
      "block": "minecraft:chiseled_stone_bricks"
    },
    {
      "x": 2,
      "y": 6,
      "z": 1,
      "block": "minecraft:stone_bricks"
    },
    {
      "x": 3,
      "y": 6,
      "z": 1,
      "block": "minecraft:stone_bricks"
    },
    {
      "x": 4,
      "y": 6,
      "z": 1,
      "block": "minecraft:stone_bricks"
    },
    {
      "x": 5,
      "y": 6,
      "z": 1,
      "block": "minecraft:stone_bricks"
    },
    {
      "x": 6,
      "y": 6,
      "z": 1,
      "block": "minecraft:stone_bricks"
    },
    {
      "x": 7,
      "y": 6,
      "z": 1,
      "block": "minecraft:chiseled_stone_bricks"
    },
    {
      "x": 8,
      "y": 6,
      "z": 1,
      "block": "minecraft:stone_bricks"
    },
    {
      "x": 9,
      "y": 6,
      "z": 1,
      "block": "minecraft:stone_bricks"
    },
    {
      "x": 10,
      "y": 6,
      "z": 1,
      "block": "minecraft:chiseled_stone_bricks"
    },
    {
      "x": 11,
      "y": 6,
      "z": 1,
      "block": "minecraft:stone_bricks"
    },
    {
      "x": 19,
      "y": 6,
      "z": 1,
      "block": "minecraft:stone_bricks"
    },
    {
      "x": 20,
      "y": 6,
      "z": 1,
      "block": "minecraft:chiseled_stone_bricks"
    },
    {
      "x": 21,
      "y": 6,
      "z": 1,
      "block": "minecraft:stone_bricks"
    },
    {
      "x": 22,
      "y": 6,
      "z": 1,
      "block": "minecraft:stone_bricks"
    },
    {
      "x": 23,
      "y": 6,
      "z": 1,
      "block": "minecraft:chiseled_stone_bricks"
    },
    {
      "x": 24,
      "y": 6,
      "z": 1,
      "block": "minecraft:stone_bricks"
    },
    {
      "x": 25,
      "y": 6,
      "z": 1,
      "block": "minecraft:stone_bricks"
    },
    {
      "x": 26,
      "y": 6,
      "z": 1,
      "block": "minecraft:stone_bricks"
    },
    {
      "x": 27,
      "y": 6,
      "z": 1,
      "block": "minecraft:stone_bricks"
    },
    {
      "x": 28,
      "y": 6,
      "z": 1,
      "block": "minecraft:stone_bricks"
    },
    {
      "x": 29,
      "y": 6,
      "z": 1,
      "block": "minecraft:chiseled_stone_bricks"
    },
    {
      "x": 1,
      "y": 6,
      "z": 2,
      "block": "minecraft:stone_bricks"
    },
    {
      "x": 2,
      "y": 6,
      "z": 2,
      "block": "minecraft:smooth_stone"
    },
    {
      "x": 3,
      "y": 6,
      "z": 2,
      "block": "minecraft:smooth_stone"
    },
    {
      "x": 4,
      "y": 6,
      "z": 2,
      "block": "minecraft:smooth_stone"
    },
    {
      "x": 5,
      "y": 6,
      "z": 2,
      "block": "minecraft:smooth_stone"
    },
    {
      "x": 6,
      "y": 6,
      "z": 2,
      "block": "minecraft:smooth_stone"
    },
    {
      "x": 7,
      "y": 6,
      "z": 2,
      "block": "minecraft:stone_bricks"
    },
    {
      "x": 8,
      "y": 6,
      "z": 2,
      "block": "minecraft:stone_bricks"
    },
    {
      "x": 22,
      "y": 6,
      "z": 2,
      "block": "minecraft:stone_bricks"
    },
    {
      "x": 23,
      "y": 6,
      "z": 2,
      "block": "minecraft:stone_bricks"
    },
    {
      "x": 24,
      "y": 6,
      "z": 2,
      "block": "minecraft:smooth_stone"
    },
    {
      "x": 25,
      "y": 6,
      "z": 2,
      "block": "minecraft:smooth_stone"
    },
    {
      "x": 26,
      "y": 6,
      "z": 2,
      "block": "minecraft:smooth_stone"
    },
    {
      "x": 27,
      "y": 6,
      "z": 2,
      "block": "minecraft:smooth_stone"
    },
    {
      "x": 28,
      "y": 6,
      "z": 2,
      "block": "minecraft:smooth_stone"
    },
    {
      "x": 29,
      "y": 6,
      "z": 2,
      "block": "minecraft:stone_bricks"
    },
    {
      "x": 1,
      "y": 6,
      "z": 3,
      "block": "minecraft:stone_bricks"
    },
    {
      "x": 2,
      "y": 6,
      "z": 3,
      "block": "minecraft:smooth_stone"
    },
    {
      "x": 3,
      "y": 6,
      "z": 3,
      "block": "minecraft:smooth_stone"
    },
    {
      "x": 4,
      "y": 6,
      "z": 3,
      "block": "minecraft:smooth_stone"
    },
    {
      "x": 5,
      "y": 6,
      "z": 3,
      "block": "minecraft:smooth_stone"
    },
    {
      "x": 6,
      "y": 6,
      "z": 3,
      "block": "minecraft:smooth_stone"
    },
    {
      "x": 7,
      "y": 6,
      "z": 3,
      "block": "minecraft:stone_bricks"
    },
    {
      "x": 8,
      "y": 6,
      "z": 3,
      "block": "minecraft:stone_bricks"
    },
    {
      "x": 13,
      "y": 6,
      "z": 3,
      "block": "minecraft:iron_bars"
    },
    {
      "x": 15,
      "y": 6,
      "z": 3,
      "block": "minecraft:iron_bars"
    },
    {
      "x": 17,
      "y": 6,
      "z": 3,
      "block": "minecraft:iron_bars"
    },
    {
      "x": 22,
      "y": 6,
      "z": 3,
      "block": "minecraft:stone_bricks"
    },
    {
      "x": 23,
      "y": 6,
      "z": 3,
      "block": "minecraft:stone_bricks"
    },
    {
      "x": 24,
      "y": 6,
      "z": 3,
      "block": "minecraft:smooth_stone"
    },
    {
      "x": 25,
      "y": 6,
      "z": 3,
      "block": "minecraft:smooth_stone"
    },
    {
      "x": 26,
      "y": 6,
      "z": 3,
      "block": "minecraft:smooth_stone"
    },
    {
      "x": 27,
      "y": 6,
      "z": 3,
      "block": "minecraft:smooth_stone"
    },
    {
      "x": 28,
      "y": 6,
      "z": 3,
      "block": "minecraft:smooth_stone"
    },
    {
      "x": 29,
      "y": 6,
      "z": 3,
      "block": "minecraft:stone_bricks"
    },
    {
      "x": 1,
      "y": 6,
      "z": 4,
      "block": "minecraft:iron_bars"
    },
    {
      "x": 2,
      "y": 6,
      "z": 4,
      "block": "minecraft:smooth_stone"
    },
    {
      "x": 3,
      "y": 6,
      "z": 4,
      "block": "minecraft:smooth_stone"
    },
    {
      "x": 4,
      "y": 6,
      "z": 4,
      "block": "minecraft:smooth_stone"
    },
    {
      "x": 5,
      "y": 6,
      "z": 4,
      "block": "minecraft:smooth_stone"
    },
    {
      "x": 6,
      "y": 6,
      "z": 4,
      "block": "minecraft:smooth_stone"
    },
    {
      "x": 7,
      "y": 6,
      "z": 4,
      "block": "minecraft:stone_bricks"
    },
    {
      "x": 8,
      "y": 6,
      "z": 4,
      "block": "minecraft:stone_bricks"
    },
    {
      "x": 22,
      "y": 6,
      "z": 4,
      "block": "minecraft:stone_bricks"
    },
    {
      "x": 23,
      "y": 6,
      "z": 4,
      "block": "minecraft:stone_bricks"
    },
    {
      "x": 24,
      "y": 6,
      "z": 4,
      "block": "minecraft:smooth_stone"
    },
    {
      "x": 25,
      "y": 6,
      "z": 4,
      "block": "minecraft:smooth_stone"
    },
    {
      "x": 26,
      "y": 6,
      "z": 4,
      "block": "minecraft:smooth_stone"
    },
    {
      "x": 27,
      "y": 6,
      "z": 4,
      "block": "minecraft:smooth_stone"
    },
    {
      "x": 28,
      "y": 6,
      "z": 4,
      "block": "minecraft:smooth_stone"
    },
    {
      "x": 29,
      "y": 6,
      "z": 4,
      "block": "minecraft:iron_bars"
    },
    {
      "x": 1,
      "y": 6,
      "z": 5,
      "block": "minecraft:stone_bricks"
    },
    {
      "x": 2,
      "y": 6,
      "z": 5,
      "block": "minecraft:smooth_stone"
    },
    {
      "x": 3,
      "y": 6,
      "z": 5,
      "block": "minecraft:smooth_stone"
    },
    {
      "x": 4,
      "y": 6,
      "z": 5,
      "block": "minecraft:smooth_stone"
    },
    {
      "x": 5,
      "y": 6,
